<?xml version="1.0" ?>
<!-- =================================================================================== -->
<!-- |    This document was autogenerated by xacro from /home/office/zbot_ws/src/zbot_description/urdf/zbot.urdf.xacro | -->
<!-- |    EDITING THIS FILE BY HAND IS NOT RECOMMENDED                                 | -->
<!-- =================================================================================== -->
<robot name="zbot">
  <link name="chassis_link">
    <inertial>
      <origin rpy="0 0 0" xyz="4.1242009807263E-13 -1.41053835278626E-13 0.0457150612516181"/>
      <mass value="2.91418586484034"/>
      <inertia ixx="0.0160414554493788" ixy="-3.80532779283033E-08" ixz="5.2791865716338E-15" iyy="0.0223949877952289" iyz="3.03477371110732E-16" izz="0.0344217543051772"/>
    </inertial>
    <visual>
      <origin rpy="0 0 0" xyz="0 0 0"/>
      <geometry>
        <mesh filename="file:///home/office/zbot_ws/install/zbot_description/share/zbot_description/meshes/chassis_link.STL"/>
      </geometry>
      <material name="">
        <color rgba="0.792156862745098 0.819607843137255 0.933333333333333 1"/>
      </material>
    </visual>
    <collision>
      <origin rpy="0 0 0" xyz="0 0 0.12"/>
      <geometry>
        <box size="0.45 0.45 0.3"/>
      </geometry>
    </collision>
  </link>
  <link name="base_footprint"/>
  <joint name="basefootprint_to_chassis" type="fixed">
    <parent link="base_footprint"/>
    <child link="chassis_link"/>
    <origin rpy="0 0 0" xyz="0 0 0.06"/>
  </joint>
  <link name="top_box_link">
    <visual>
      <origin rpy="0 0 0" xyz="0 0 0"/>
      <geometry>
        <box size="0.45 0.45 0.02"/>
      </geometry>
      <material name="">
        <color rgba="0.6 0.6 0.6 1"/>
      </material>
    </visual>
    <collision>
      <origin rpy="0 0 0" xyz="0 0 0"/>
      <geometry>
        <box size="0.45 0.45 0.02"/>
      </geometry>
    </collision>
    <inertial>
      <origin rpy="0 0 0" xyz="0 0 0"/>
      <mass value="1.0"/>
      <inertia ixx="0.01" ixy="0.0" ixz="0.0" iyy="0.01" iyz="0.0" izz="0.01"/>
    </inertial>
  </link>
  <joint name="chassis_to_top_box" type="fixed">
    <parent link="chassis_link"/>
    <child link="top_box_link"/>
    <origin rpy="0 0 0" xyz="0 0 0.26"/>
  </joint>
  <link name="Left_wheel_link">
    <inertial>
      <origin rpy="0 0 0" xyz="1.38777878078145E-16 0.0172531056477295 7.63278329429795E-16"/>
      <mass value="0.422964399925245"/>
      <inertia ixx="0.000450352731222891" ixy="8.63588855368215E-21" ixz="-2.55358655482607E-20" iyy="0.000799166716964205" iyz="-1.56617535979576E-20" izz="0.000450352731222891"/>
    </inertial>
    <visual>
      <origin rpy="0 0 0" xyz="0 0 0"/>
      <geometry>
        <mesh filename="file:///home/office/zbot_ws/install/zbot_description/share/zbot_description/meshes/Left_wheel_link.STL"/>
      </geometry>
      <material name="">
        <color rgba="0.792156862745098 0.819607843137255 0.933333333333333 1"/>
      </material>
    </visual>
    <collision>
      <origin rpy="0 0 0" xyz="0 0 0"/>
      <geometry>
        <mesh filename="file:///home/office/zbot_ws/install/zbot_description/share/zbot_description/meshes/Left_wheel_link.STL"/>
      </geometry>
    </collision>
  </link>
  <joint name="Left_wheel_joint" type="continuous">
    <origin rpy="0 0 0" xyz="0 -0.195500000000004 0"/>
    <parent link="chassis_link"/>
    <child link="Left_wheel_link"/>
    <axis xyz="0 1 0"/>
    <limit effort="24" velocity="9.42"/>
  </joint>
  <link name="Right_wheel_link">
    <inertial>
      <origin rpy="0 0 0" xyz="-1.66533453693773E-16 -0.0172531056477289 -4.16333634234434E-17"/>
      <mass value="0.422964399925245"/>
      <inertia ixx="0.000450352731222891" ixy="2.9978516071709E-19" ixz="1.86430677315541E-20" iyy="0.000799166716964206" iyz="-6.95386833210546E-19" izz="0.000450352731222891"/>
    </inertial>
    <visual>
      <origin rpy="0 0 0" xyz="0 0 0"/>
      <geometry>
        <mesh filename="file:///home/office/zbot_ws/install/zbot_description/share/zbot_description/meshes/Right_wheel_link.STL"/>
      </geometry>
      <material name="">
        <color rgba="0.792156862745098 0.819607843137255 0.933333333333333 1"/>
      </material>
    </visual>
    <collision>
      <origin rpy="0 0 0" xyz="0 0 0"/>
      <geometry>
        <mesh filename="file:///home/office/zbot_ws/install/zbot_description/share/zbot_description/meshes/Right_wheel_link.STL"/>
      </geometry>
    </collision>
  </link>
  <joint name="Right_wheel_joint" type="continuous">
    <origin rpy="0 0 0" xyz="0 0.195500000000003 0"/>
    <parent link="chassis_link"/>
    <child link="Right_wheel_link"/>
    <axis xyz="0 -1 0"/>
    <limit effort="24" velocity="9.42"/>
  </joint>
  <link name="holder1_Link">
    <inertial>
      <origin rpy="0 0 0" xyz="0.0149538369402379 0 -0.00548508947688803"/>
      <mass value="0.0110673356545045"/>
      <inertia ixx="3.36759375651107E-06" ixy="1.91654214425208E-21" ixz="5.32584414214133E-07" iyy="3.65279992142393E-06" iyz="-2.64785319973256E-22" izz="5.74768206818997E-06"/>
    </inertial>
    <visual>
      <origin rpy="0 0 0" xyz="0 0 0"/>
      <geometry>
        <mesh filename="file:///home/office/zbot_ws/install/zbot_description/share/zbot_description/meshes/holder1_Link.STL"/>
      </geometry>
      <material name="">
        <color rgba="0 0 0 1"/>
      </material>
    </visual>
    <collision>
      <origin rpy="0 0 0" xyz="0 0 0"/>
      <geometry>
        <mesh filename="file:///home/office/zbot_ws/install/zbot_description/share/zbot_description/meshes/holder1_Link.STL"/>
      </geometry>
    </collision>
  </link>
  <joint name="holder1_joint" type="continuous">
    <origin rpy="0 0 0" xyz="0.13 0.1295 -0.00949999999999611"/>
    <parent link="chassis_link"/>
    <child link="holder1_Link"/>
    <axis xyz="0 0 1"/>
    <limit effort="0" velocity="0"/>
  </joint>
  <link name="wheel1_Link">
    <inertial>
      <origin rpy="0 0 0" xyz="5.55111512312578E-17 0 3.25260651745651E-18"/>
      <mass value="0.07386669726753"/>
      <inertia ixx="1.38792446386636E-05" ixy="-7.67863316734526E-22" ixz="-1.59131939955441E-22" iyy="2.33141763250642E-05" iyz="2.27558867913594E-22" izz="1.38792446386636E-05"/>
    </inertial>
    <visual>
      <origin rpy="0 0 0" xyz="0 0 0"/>
      <geometry>
        <mesh filename="file:///home/office/zbot_ws/install/zbot_description/share/zbot_description/meshes/wheel1_Link.STL"/>
      </geometry>
      <material name="">
        <color rgba="0.909803921568627 0.443137254901961 0.0313725490196078 1"/>
      </material>
    </visual>
    <collision>
      <origin rpy="0 0 0" xyz="0 0 0"/>
      <geometry>
        <mesh filename="file:///home/office/zbot_ws/install/zbot_description/share/zbot_description/meshes/wheel1_Link.STL"/>
      </geometry>
    </collision>
  </link>
  <joint name="wheel1_joint" type="continuous">
    <origin rpy="0 0 0" xyz="0.0350000000000004 0 -0.03"/>
    <parent link="holder1_Link"/>
    <child link="wheel1_Link"/>
    <axis xyz="0 -1 0"/>
    <limit effort="0" velocity="0"/>
  </joint>
  <link name="holder2_Link">
    <inertial>
      <origin rpy="0 0 0" xyz="0.0149538369402378 -1.38777878078145E-17 -0.00548508947688803"/>
      <mass value="0.0110673356545045"/>
      <inertia ixx="3.36759375651108E-06" ixy="2.21298389542766E-21" ixz="5.32584414214133E-07" iyy="3.65279992142394E-06" iyz="-2.93180920139946E-22" izz="5.74768206818998E-06"/>
    </inertial>
    <visual>
      <origin rpy="0 0 0" xyz="0 0 0"/>
      <geometry>
        <mesh filename="file:///home/office/zbot_ws/install/zbot_description/share/zbot_description/meshes/holder2_Link.STL"/>
      </geometry>
      <material name="">
        <color rgba="0 0 0 1"/>
      </material>
    </visual>
    <collision>
      <origin rpy="0 0 0" xyz="0 0 0"/>
      <geometry>
        <mesh filename="file:///home/office/zbot_ws/install/zbot_description/share/zbot_description/meshes/holder2_Link.STL"/>
      </geometry>
    </collision>
  </link>
  <joint name="holder2_joint" type="continuous">
    <origin rpy="0 0 0" xyz="-0.130000000000001 0.1295 -0.00949999999999698"/>
    <parent link="chassis_link"/>
    <child link="holder2_Link"/>
    <axis xyz="0 0 1"/>
    <limit effort="0" velocity="0"/>
  </joint>
  <link name="wheel2_Link">
    <inertial>
      <origin rpy="0 0 0" xyz="5.55111512312578E-17 -1.38777878078145E-17 3.25260651745651E-18"/>
      <mass value="0.07386669726753"/>
      <inertia ixx="1.38792446386636E-05" ixy="-7.67404920811736E-22" ixz="-1.57821214113714E-22" iyy="2.33141763250642E-05" iyz="2.36988726896699E-22" izz="1.38792446386636E-05"/>
    </inertial>
    <visual>
      <origin rpy="0 0 0" xyz="0 0 0"/>
      <geometry>
        <mesh filename="file:///home/office/zbot_ws/install/zbot_description/share/zbot_description/meshes/wheel2_Link.STL"/>
      </geometry>
      <material name="">
        <color rgba="0.909803921568627 0.443137254901961 0.0313725490196078 1"/>
      </material>
    </visual>
    <collision>
      <origin rpy="0 0 0" xyz="0 0 0"/>
      <geometry>
        <mesh filename="file:///home/office/zbot_ws/install/zbot_description/share/zbot_description/meshes/wheel2_Link.STL"/>
      </geometry>
    </collision>
  </link>
  <joint name="wheel2_joint" type="continuous">
    <origin rpy="0 0 0" xyz="0.0350000000000004 0 -0.03"/>
    <parent link="holder2_Link"/>
    <child link="wheel2_Link"/>
    <axis xyz="0 -1 0"/>
    <limit effort="0" velocity="0"/>
  </joint>
  <link name="holder3_Link">
    <inertial>
      <origin rpy="0 0 0" xyz="0.0149538369402379 1.11022302462516E-16 -0.00548508947688804"/>
      <mass value="0.0110673356545045"/>
      <inertia ixx="3.36759375651107E-06" ixy="-8.59900995484746E-21" ixz="5.32584414214132E-07" iyy="3.65279992142393E-06" iyz="9.43655140551764E-21" izz="5.74768206818997E-06"/>
    </inertial>
    <visual>
      <origin rpy="0 0 0" xyz="0 0 0"/>
      <geometry>
        <mesh filename="file:///home/office/zbot_ws/install/zbot_description/share/zbot_description/meshes/holder3_Link.STL"/>
      </geometry>
      <material name="">
        <color rgba="0 0 0 1"/>
      </material>
    </visual>
    <collision>
      <origin rpy="0 0 0" xyz="0 0 0"/>
      <geometry>
        <mesh filename="file:///home/office/zbot_ws/install/zbot_description/share/zbot_description/meshes/holder3_Link.STL"/>
      </geometry>
    </collision>
  </link>
  <joint name="holder3_joint" type="continuous">
    <origin rpy="0 0 0" xyz="0.13 -0.1295 -0.00949999999999693"/>
    <parent link="chassis_link"/>
    <child link="holder3_Link"/>
    <axis xyz="0 0 1"/>
    <limit effort="0" velocity="0"/>
  </joint>
  <link name="wheel3_Link">
    <inertial>
      <origin rpy="0 0 0" xyz="-2.91433543964104E-16 0 -8.16295815664336E-16"/>
      <mass value="0.0738666972675301"/>
      <inertia ixx="1.38792446386636E-05" ixy="-7.76245413608397E-22" ixz="-1.17777958037584E-22" iyy="2.33141763250642E-05" iyz="2.28606630022829E-22" izz="1.38792446386636E-05"/>
    </inertial>
    <visual>
      <origin rpy="0 0 0" xyz="0 0 0"/>
      <geometry>
        <mesh filename="file:///home/office/zbot_ws/install/zbot_description/share/zbot_description/meshes/wheel3_Link.STL"/>
      </geometry>
      <material name="">
        <color rgba="0.909803921568627 0.443137254901961 0.0313725490196078 1"/>
      </material>
    </visual>
    <collision>
      <origin rpy="0 0 0" xyz="0 0 0"/>
      <geometry>
        <mesh filename="file:///home/office/zbot_ws/install/zbot_description/share/zbot_description/meshes/wheel3_Link.STL"/>
      </geometry>
    </collision>
  </link>
  <joint name="wheel3_joint" type="continuous">
    <origin rpy="0 0 0" xyz="0.0350000000000007 0 -0.0299999999999991"/>
    <parent link="holder3_Link"/>
    <child link="wheel3_Link"/>
    <axis xyz="0 -1 0"/>
    <limit effort="0" velocity="0"/>
  </joint>
  <link name="holder4_Link">
    <inertial>
      <origin rpy="0 0 0" xyz="0.0149538369402379 5.55111512312578E-17 -0.00548508947688803"/>
      <mass value="0.0110673356545044"/>
      <inertia ixx="3.36759375651107E-06" ixy="-5.99260130111312E-21" ixz="5.32584414214132E-07" iyy="3.65279992142393E-06" iyz="7.6641911408224E-21" izz="5.74768206818997E-06"/>
    </inertial>
    <visual>
      <origin rpy="0 0 0" xyz="0 0 0"/>
      <geometry>
        <mesh filename="file:///home/office/zbot_ws/install/zbot_description/share/zbot_description/meshes/holder4_Link.STL"/>
      </geometry>
      <material name="">
        <color rgba="0 0 0 1"/>
      </material>
    </visual>
    <collision>
      <origin rpy="0 0 0" xyz="0 0 0"/>
      <geometry>
        <mesh filename="file:///home/office/zbot_ws/install/zbot_description/share/zbot_description/meshes/holder4_Link.STL"/>
      </geometry>
    </collision>
  </link>
  <joint name="holder4_joint" type="continuous">
    <origin rpy="0 0 0" xyz="-0.13 -0.1295 -0.0095"/>
    <parent link="chassis_link"/>
    <child link="holder4_Link"/>
    <axis xyz="0 0 1"/>
    <limit effort="0" velocity="0"/>
  </joint>
  <link name="wheel4_Link">
    <inertial>
      <origin rpy="0 0 0" xyz="3.33066907387547E-16 5.55111512312578E-17 1.63714528045311E-17"/>
      <mass value="0.0738666972675301"/>
      <inertia ixx="1.38792446386636E-05" ixy="-7.76834779794841E-22" ixz="-1.16467232195856E-22" iyy="2.33141763250642E-05" iyz="2.36988726896699E-22" izz="1.38792446386636E-05"/>
    </inertial>
    <visual>
      <origin rpy="0 0 0" xyz="0 0 0"/>
      <geometry>
        <mesh filename="file:///home/office/zbot_ws/install/zbot_description/share/zbot_description/meshes/wheel4_Link.STL"/>
      </geometry>
      <material name="">
        <color rgba="0.909803921568627 0.443137254901961 0.0313725490196078 1"/>
      </material>
    </visual>
    <collision>
      <origin rpy="0 0 0" xyz="0 0 0"/>
      <geometry>
        <mesh filename="file:///home/office/zbot_ws/install/zbot_description/share/zbot_description/meshes/wheel4_Link.STL"/>
      </geometry>
    </collision>
  </link>
  <joint name="wheel4_joint" type="continuous">
    <origin rpy="0 0 0" xyz="0.0350000000000001 0 -0.03"/>
    <parent link="holder4_Link"/>
    <child link="wheel4_Link"/>
    <axis xyz="0 -1 0"/>
    <limit effort="0" velocity="0"/>
  </joint>
  <link name="torso_footprint"/>
  <link name="torso_link">
    <inertial>
      <origin rpy="0 0 0" xyz="0.018596 -3.9839E-08 -0.30971"/>
      <mass value="8.7003"/>
      <inertia ixx="0.33953" ixy="1.241E-07" ixz="3.4609E-05" iyy="0.32865" iyz="6.853E-09" izz="0.025969"/>
    </inertial>
    <visual>
      <origin rpy="0 0 0" xyz="0 0 0"/>
      <geometry>
        <mesh filename="file:///home/office/zbot_ws/install/zbot_description/share/zbot_description/meshes/torso_link.STL"/>
      </geometry>
      <material name="">
        <color rgba="1 1 1 1"/>
      </material>
    </visual>
    <collision>
      <origin rpy="0 0 0" xyz="0 0 0"/>
      <geometry>
        <mesh filename="file:///home/office/zbot_ws/install/zbot_description/share/zbot_description/meshes/torso_link.STL"/>
      </geometry>
    </collision>
  </link>
  <joint name="footprint_to_torso" type="fixed">
    <parent link="torso_footprint"/>
    <child link="torso_link"/>
    <origin rpy="0 0 0" xyz="0 0 1.085"/>
  </joint>
  <link name="T2RS_link">
    <inertial>
      <origin rpy="0 0 0" xyz="-1.1391E-05 -0.02751 0.026802"/>
      <mass value="0.49232"/>
      <inertia ixx="0.00053947" ixy="-1.1182E-07" ixz="-6.3739E-08" iyy="0.00105" iyz="7.5262E-05" izz="0.00087713"/>
    </inertial>
    <visual>
      <origin rpy="0 0 0" xyz="0 0 0"/>
      <geometry>
        <mesh filename="file:///home/office/zbot_ws/install/zbot_description/share/zbot_description/meshes/T2RS_link.STL"/>
      </geometry>
      <material name="">
        <color rgba="0.89412 0.89412 0.89412 1"/>
      </material>
    </visual>
    <collision>
      <origin rpy="1.44 0 0" xyz="0 -0.046 0.06"/>
      <geometry>
        <cylinder length="0.06" radius="0.053"/>
      </geometry>
    </collision>
  </link>
  <joint name="T2RS_joint" type="fixed">
    <origin rpy="0 0 0" xyz="0 -0.062 -0.046174"/>
    <parent link="torso_link"/>
    <child link="T2RS_link"/>
    <axis xyz="0 0 0"/>
  </joint>
  <link name="RSP_link">
    <inertial>
      <origin rpy="0 0 0" xyz="-0.0015388 -0.053054 -3.8328E-05"/>
      <mass value="0.17559"/>
      <inertia ixx="0.00019619" ixy="8.3208E-08" ixz="-1.6412E-08" iyy="0.00012479" iyz="-7.8681E-08" izz="0.00010732"/>
    </inertial>
    <visual>
      <origin rpy="0 0 0" xyz="0 0 0"/>
      <geometry>
        <mesh filename="file:///home/office/zbot_ws/install/zbot_description/share/zbot_description/meshes/RSP_link.STL"/>
      </geometry>
      <material name="">
        <color rgba="0.86667 0.9098 1 1"/>
      </material>
    </visual>
    <!-- Main cylindrical body -->
    <collision>
      <origin rpy="0 1.57 0" xyz="0 -0.068 0"/>
      <geometry>
        <cylinder length="0.05" radius="0.053"/>
      </geometry>
    </collision>
    <!-- Side mounting bracket -->
    <collision>
      <origin rpy="0 0 0" xyz="0 -0.0125 0"/>
      <geometry>
        <box size="0.05 0.02 0.05"/>
      </geometry>
    </collision>
  </link>
  <joint name="RSP_joint" type="revolute">
    <origin rpy="-0.13963 0 0" xyz="0 -0.078272 0.065888"/>
    <parent link="T2RS_link"/>
    <child link="RSP_link"/>
    <axis xyz="0 1 0"/>
    <limit effort="35" lower="-1.57" upper="1.57" velocity="10.47"/>
    <dynamics damping="0.05" friction="0.05"/>
  </joint>
  <link name="RSY_link">
    <inertial>
      <origin rpy="0 0 0" xyz="-0.00694 -8.3267E-17 -0.037821"/>
      <mass value="0.053339"/>
      <inertia ixx="2.5402E-05" ixy="8.1403E-22" ixz="-8.1208E-07" iyy="2.2164E-05" iyz="-7.2518E-21" izz="1.1182E-05"/>
    </inertial>
    <visual>
      <origin rpy="0 0 0" xyz="0 0 0"/>
      <geometry>
        <mesh filename="file:///home/office/zbot_ws/install/zbot_description/share/zbot_description/meshes/RSY_link.STL"/>
      </geometry>
      <material name="">
        <color rgba="0.86667 0.9098 1 1"/>
      </material>
    </visual>
    <collision>
      <!-- Vertical plate -->
      <origin rpy="0 0 0" xyz="0 0 -0.03"/>
      <geometry>
        <box size="0.01 0.05 0.09"/>
      </geometry>
    </collision>
    <collision>
      <!-- Bottom horizontal plate -->
      <origin rpy="0 0 0" xyz="-0.02 0 -0.065"/>
      <geometry>
        <box size="0.05 0.05 0.01"/>
      </geometry>
    </collision>
  </link>
  <joint name="RSY_joint" type="revolute">
    <origin rpy="0.13963 0 0" xyz="0.031 -0.06875 0"/>
    <parent link="RSP_link"/>
    <child link="RSY_link"/>
    <axis xyz="-1 0 0"/>
    <limit effort="35" lower="-1.57" upper="1.57" velocity="10.47"/>
    <dynamics damping="0.05" friction="0.05"/>
  </joint>
  <link name="RSR_link">
    <inertial>
      <origin rpy="0 0 0" xyz="5.8391E-05 0.0011415 -0.11682"/>
      <mass value="0.35852"/>
      <inertia ixx="0.00067036" ixy="6.1426E-08" ixz="-5.8526E-09" iyy="0.00058704" iyz="3.8462E-06" izz="0.00035439"/>
    </inertial>
    <visual>
      <origin rpy="0 0 0" xyz="0 0 0"/>
      <geometry>
        <mesh filename="file:///home/office/zbot_ws/install/zbot_description/share/zbot_description/meshes/RSR_link.STL"/>
      </geometry>
      <material name="">
        <color rgba="0.89412 0.89412 0.89412 1"/>
      </material>
    </visual>
    <collision name="RSR_link_middlepart">
      <origin rpy="0 0 0" xyz="0 0 -0.09"/>
      <geometry>
        <cylinder length="0.18" radius="0.055"/>
      </geometry>
    </collision>
    <collision name="RSR_link_elbowmotor">
      <origin rpy="1.57 0 0" xyz="0 0 -0.23"/>
      <geometry>
        <cylinder length="0.06" radius="0.05"/>
      </geometry>
    </collision>
  </link>
  <joint name="RSR_joint" type="revolute">
    <origin rpy="0 0 0" xyz="-0.0275 0 -0.07875"/>
    <parent link="RSY_link"/>
    <child link="RSR_link"/>
    <axis xyz="0 0 1"/>
    <limit effort="25" lower="-1.57" upper="1.57" velocity="10.47"/>
    <dynamics damping="0.05" friction="0.05"/>
  </joint>
  <link name="REP_link">
    <inertial>
      <origin rpy="0 0 0" xyz="-2.5968E-07 -0.019327 -0.081159"/>
      <mass value="0.16062"/>
      <inertia ixx="6.3488E-05" ixy="-5.7068E-09" ixz="8.1084E-10" iyy="6.5851E-05" iyz="-3.6027E-07" izz="5.6992E-05"/>
    </inertial>
    <visual>
      <origin rpy="0 0 0" xyz="0 0 0"/>
      <geometry>
        <mesh filename="file:///home/office/zbot_ws/install/zbot_description/share/zbot_description/meshes/REP_link.STL"/>
      </geometry>
      <material name="">
        <color rgba="1 1 1 1"/>
      </material>
    </visual>
    <collision name="REP_link_main">
      <origin rpy="0 0 0" xyz="0 -0.025 -0.093"/>
      <geometry>
        <cylinder length="0.05" radius="0.03"/>
      </geometry>
    </collision>
    <collision name="REP_link_mount">
      <origin rpy="0 0 0" xyz="0 0 -0.03"/>
      <geometry>
        <box size="0.05 0.005 0.08"/>
      </geometry>
    </collision>
  </link>
  <joint name="REP_joint" type="revolute">
    <origin rpy="0 0 0" xyz="1.4698E-05 0.028015 -0.22617"/>
    <parent link="RSR_link"/>
    <child link="REP_link"/>
    <axis xyz="0 1 0"/>
    <limit effort="25" lower="-1.57" upper="1.57" velocity="10.47"/>
    <dynamics damping="0.05" friction="0.05"/>
  </joint>
  <link name="RWR_link">
    <inertial>
      <origin rpy="0 0 0" xyz="2.3009E-10 0.0050603 -0.04305"/>
      <mass value="0.15675"/>
      <inertia ixx="5.9396E-05" ixy="-6.4446E-13" ixz="-5.7068E-09" iyy="5.8786E-05" iyz="6.5271E-07" izz="5.9559E-05"/>
    </inertial>
    <visual>
      <origin rpy="0 0 0" xyz="0 0 0"/>
      <geometry>
        <mesh filename="file:///home/office/zbot_ws/install/zbot_description/share/zbot_description/meshes/RWR_link.STL"/>
      </geometry>
      <material name="">
        <color rgba="1 1 1 1"/>
      </material>
    </visual>
    <collision name="RWR_link_main">
      <origin rpy="1.57 0 0" xyz="0 0 -0.053"/>
      <geometry>
        <cylinder length="0.05" radius="0.03"/>
      </geometry>
    </collision>
    <collision name="RWR_link_mount">
      <origin rpy="0 0 0" xyz="0 0.03 -0.033"/>
      <geometry>
        <box size="0.05 0.004 0.06"/>
      </geometry>
    </collision>
  </link>
  <joint name="RWR_joint" type="revolute">
    <origin rpy="0 0 0" xyz="0 -0.0235 -0.1244"/>
    <parent link="REP_link"/>
    <child link="RWR_link"/>
    <axis xyz="0 0 1"/>
    <limit effort="7" lower="-1.57" upper="1.57" velocity="10.47"/>
    <dynamics damping="0.05" friction="0.05"/>
  </joint>
  <link name="RWP_link">
    <inertial>
      <origin rpy="0 0 0" xyz="-0.0016414 0.025392 -0.064653"/>
      <mass value="0.17262"/>
      <inertia ixx="6.9076E-05" ixy="6.4136E-13" ixz="-2.1656E-06" iyy="7.0471E-05" iyz="3.4482E-06" izz="6.5933E-05"/>
    </inertial>
    <visual>
      <origin rpy="0 0 0" xyz="0 0 0"/>
      <geometry>
        <mesh filename="file:///home/office/zbot_ws/install/zbot_description/share/zbot_description/meshes/RWP_link.STL"/>
      </geometry>
      <material name="">
        <color rgba="1 1 1 1"/>
      </material>
    </visual>
    <collision name="RWP_link_main">
      <origin rpy="0 1.57 0" xyz="-0.0015 0.026 -0.078"/>
      <geometry>
        <cylinder length="0.053" radius="0.03"/>
      </geometry>
    </collision>
    <collision name="RWP_link_mount">
      <origin rpy="0 0 0" xyz="0 0 -0.0115"/>
      <geometry>
        <box size="0.036 0.004 0.056"/>
      </geometry>
    </collision>
    <collision name="RWP_link_mount1">
      <origin rpy="0 0 0" xyz="-0.027 0.028 -0.0442"/>
      <geometry>
        <box size="0.003 0.0271 0.0124"/>
      </geometry>
    </collision>
    <collision name="RWP_link_mount2">
      <origin rpy="0 0 0" xyz="-0.0027 0.0212 -0.038"/>
      <geometry>
        <box size="0.0415 0.0435 0.006"/>
      </geometry>
    </collision>
  </link>
  <joint name="RWP_joint" type="revolute">
    <origin rpy="0 0 0" xyz="0 -0.0284 -0.049899"/>
    <parent link="RWR_link"/>
    <child link="RWP_link"/>
    <axis xyz="0 1 0"/>
    <limit effort="7" lower="-1.57" upper="1.57" velocity="10.47"/>
    <dynamics damping="0.05" friction="0.05"/>
  </joint>
  <link name="RWY_link">
    <inertial>
      <origin rpy="0 0 0" xyz="-0.025989 -8.2357E-07 -0.072885"/>
      <mass value="0.14311"/>
      <inertia ixx="0.0001351" ixy="-2.218E-09" ixz="-3.6162E-06" iyy="3.6435E-05" iyz="3.4239E-10" izz="0.00014744"/>
    </inertial>
    <visual>
      <origin rpy="0 0 0" xyz="0 0 0"/>
      <geometry>
        <mesh filename="file:///home/office/zbot_ws/install/zbot_description/share/zbot_description/meshes/RWY_link.STL"/>
      </geometry>
      <material name="">
        <color rgba="1 1 1 1"/>
      </material>
    </visual>
    <collision name="RWY_link_main">
      <origin rpy="0 0 0" xyz="-0.0304 0 -0.0583"/>
      <geometry>
        <cylinder length="0.0471" radius="0.023"/>
      </geometry>
    </collision>
    <collision name="RWY_link_mount">
      <origin rpy="0 0 0" xyz="0 0 -0.0075"/>
      <geometry>
        <box size="0.003 0.04 0.055"/>
      </geometry>
    </collision>
    <collision name="RWY_link_pinion">
      <origin rpy="0 0 0" xyz="-0.0304 0 -0.094"/>
      <geometry>
        <box size="0.0535 0.126 0.024"/>
      </geometry>
    </collision>
  </link>
  <joint name="RWY_joint" type="revolute">
    <origin rpy="0 0 0" xyz="0.0304 0.0284 -0.076"/>
    <parent link="RWP_link"/>
    <child link="RWY_link"/>
    <axis xyz="-1 0 0"/>
    <limit effort="7" lower="-1.57" upper="1.57" velocity="10.47"/>
    <dynamics damping="0.05" friction="0.05"/>
  </joint>
  <link name="RGRF_link">
    <inertial>
      <origin rpy="0 0 0" xyz="-1.4993E-10 1.2259E-05 -0.0098954"/>
      <mass value="0.025769"/>
      <inertia ixx="4.2118E-06" ixy="1.4492E-22" ixz="6.0762E-22" iyy="1.2066E-05" iyz="1.8787E-07" izz="8.6788E-06"/>
    </inertial>
    <visual>
      <origin rpy="0 0 0" xyz="0 0 0"/>
      <geometry>
        <mesh filename="file:///home/office/zbot_ws/install/zbot_description/share/zbot_description/meshes/RGRF_link.STL"/>
      </geometry>
      <material name="">
        <color rgba="1 1 1 1"/>
      </material>
    </visual>
    <collision name="RGRF_link_box">
      <origin rpy="0 0 0" xyz="0 0 -0.016"/>
      <geometry>
        <box size="0.0535 0.014 0.035"/>
      </geometry>
    </collision>
  </link>
  <joint name="RGRF_joint" type="prismatic">
    <origin rpy="0 0 0" xyz="-0.0304 -0.0515 -0.10975"/>
    <parent link="RWY_link"/>
    <child link="RGRF_link"/>
    <axis xyz="0 1 0"/>
    <limit effort="1.8" lower="0" upper="0.04" velocity="0.3"/>
  </joint>
  <link name="RGLF_link">
    <inertial>
      <origin rpy="0 0 0" xyz="1.0343E-11 -1.2259E-05 -0.0098955"/>
      <mass value="0.025769"/>
      <inertia ixx="4.2118E-06" ixy="-3.6494E-22" ixz="2.7143E-21" iyy="1.2066E-05" iyz="-1.8787E-07" izz="8.6788E-06"/>
    </inertial>
    <visual>
      <origin rpy="0 0 0" xyz="0 0 0"/>
      <geometry>
        <mesh filename="file:///home/office/zbot_ws/install/zbot_description/share/zbot_description/meshes/RGLF_link.STL"/>
      </geometry>
      <material name="">
        <color rgba="1 1 1 1"/>
      </material>
    </visual>
    <collision name="RGLF_link_box">
      <origin rpy="0 0 0" xyz="0 0 -0.016"/>
      <geometry>
        <box size="0.0535 0.014 0.035"/>
      </geometry>
    </collision>
  </link>
  <joint name="RGLF_joint" type="prismatic">
    <origin rpy="0 0 0" xyz="-0.0304 0.0515 -0.10975"/>
    <parent link="RWY_link"/>
    <child link="RGLF_link"/>
    <axis xyz="0 1 0"/>
    <mimic joint="RGRF_joint" multiplier="-1.0"/>
    <limit effort="1.8" lower="-0.04" upper="0" velocity="0.3"/>
    <dynamics damping="0.05" friction="0.05"/>
  </joint>
  <link name="T2LS_link">
    <inertial>
      <origin rpy="0 0 0" xyz="1.1662E-05 0.027974 0.026802"/>
      <mass value="0.49232"/>
      <inertia ixx="0.00053947" ixy="-1.1182E-07" ixz="6.3739E-08" iyy="0.00105" iyz="-7.5262E-05" izz="0.00087713"/>
    </inertial>
    <visual>
      <origin rpy="0 0 0" xyz="0 0 0"/>
      <geometry>
        <mesh filename="file:///home/office/zbot_ws/install/zbot_description/share/zbot_description/meshes/T2LS_link.STL"/>
      </geometry>
      <material name="">
        <color rgba="0.77647 0.75686 0.73725 1"/>
      </material>
    </visual>
    <collision>
      <origin rpy="1.7 0 0" xyz="0 0.046 0.06"/>
      <geometry>
        <cylinder length="0.06" radius="0.053"/>
      </geometry>
    </collision>
  </link>
  <joint name="T2LS_joint" type="fixed">
    <origin rpy="0 0 0" xyz="0 0.061536 -0.046174"/>
    <parent link="torso_link"/>
    <child link="T2LS_link"/>
    <axis xyz="0 0 0"/>
  </joint>
  <link name="LSP_link">
    <inertial>
      <origin rpy="0 0 0" xyz="-0.0015388 0.053054 3.8328E-05"/>
      <mass value="0.17559"/>
      <inertia ixx="0.00019619" ixy="-8.3208E-08" ixz="1.6412E-08" iyy="0.00012479" iyz="-7.8681E-08" izz="0.00010732"/>
    </inertial>
    <visual>
      <origin rpy="0 0 0" xyz="0 0 0"/>
      <geometry>
        <mesh filename="file:///home/office/zbot_ws/install/zbot_description/share/zbot_description/meshes/LSP_link.STL"/>
      </geometry>
      <material name="">
        <color rgba="0.86667 0.9098 1 1"/>
      </material>
    </visual>
    <collision>
      <origin rpy="0 1.57 0" xyz="0 0.068 0"/>
      <geometry>
        <cylinder length="0.05" radius="0.053"/>
      </geometry>
    </collision>
    <!-- Side mounting bracket -->
    <collision>
      <origin rpy="0 0 0" xyz="0 0.0125 0"/>
      <geometry>
        <box size="0.05 0.02 0.05"/>
      </geometry>
    </collision>
  </link>
  <joint name="LSP_joint" type="revolute">
    <origin rpy="0.13963 0 0" xyz="0 0.078736 0.065888"/>
    <parent link="T2LS_link"/>
    <child link="LSP_link"/>
    <axis xyz="0 -1 0"/>
    <limit effort="35" lower="-1.57" upper="1.57" velocity="10.47"/>
    <dynamics damping="0.05" friction="0.05"/>
  </joint>
  <link name="LSY_link">
    <inertial>
      <origin rpy="0 0 0" xyz="-0.00694 -4.0801E-15 -0.037821"/>
      <mass value="0.053339"/>
      <inertia ixx="2.5402E-05" ixy="-1.2859E-21" ixz="-8.1208E-07" iyy="2.2164E-05" iyz="-1.4228E-20" izz="1.1182E-05"/>
    </inertial>
    <visual>
      <origin rpy="0 0 0" xyz="0 0 0"/>
      <geometry>
        <mesh filename="file:///home/office/zbot_ws/install/zbot_description/share/zbot_description/meshes/LSY_link.STL"/>
      </geometry>
      <material name="">
        <color rgba="1 1 1 1"/>
      </material>
    </visual>
    <collision>
      <!-- Vertical plate -->
      <origin rpy="0 0 0" xyz="0 0 -0.03"/>
      <geometry>
        <box size="0.01 0.05 0.09"/>
      </geometry>
    </collision>
    <collision>
      <!-- Bottom horizontal plate -->
      <origin rpy="0 0 0" xyz="-0.02 0 -0.065"/>
      <geometry>
        <box size="0.05 0.05 0.01"/>
      </geometry>
    </collision>
  </link>
  <joint name="LSY_joint" type="revolute">
    <origin rpy="-0.13963 0 0" xyz="0.031 0.06875 0"/>
    <parent link="LSP_link"/>
    <child link="LSY_link"/>
    <axis xyz="-1 0 0"/>
    <limit effort="35" lower="-1.57" upper="1.57" velocity="10.47"/>
    <dynamics damping="0.05" friction="0.05"/>
  </joint>
  <link name="LSR_link">
    <inertial>
      <origin rpy="0 0 0" xyz="-5.7058E-05 -0.0012378 -0.11682"/>
      <mass value="0.35852"/>
      <inertia ixx="0.00067036" ixy="6.1426E-08" ixz="5.6197E-09" iyy="0.00058704" iyz="-3.9806E-06" izz="0.00035439"/>
    </inertial>
    <visual>
      <origin rpy="0 0 0" xyz="0 0 0"/>
      <geometry>
        <mesh filename="file:///home/office/zbot_ws/install/zbot_description/share/zbot_description/meshes/LSR_link.STL"/>
      </geometry>
      <material name="">
        <color rgba="0.89412 0.89412 0.89412 1"/>
      </material>
    </visual>
    <collision name="LSR_link_middlepart">
      <origin rpy="0 0 0" xyz="0 0 -0.09"/>
      <geometry>
        <cylinder length="0.18" radius="0.055"/>
      </geometry>
    </collision>
    <collision name="LSR_link_elbowmotor">
      <origin rpy="1.57 0 0" xyz="0 0 -0.23"/>
      <geometry>
        <cylinder length="0.06" radius="0.05"/>
      </geometry>
    </collision>
  </link>
  <joint name="LSR_joint" type="revolute">
    <origin rpy="0 0 0" xyz="-0.0275 0 -0.07875"/>
    <parent link="LSY_link"/>
    <child link="LSR_link"/>
    <axis xyz="0 0 1"/>
    <limit effort="25" lower="-1.57" upper="1.57" velocity="10.47"/>
    <dynamics damping="0.05" friction="0.05"/>
  </joint>
  <link name="LEP_link">
    <inertial>
      <origin rpy="0 0 0" xyz="2.7528E-07 0.019327 -0.081159"/>
      <mass value="0.16062"/>
      <inertia ixx="6.3488E-05" ixy="-5.7068E-09" ixz="-8.1088E-10" iyy="6.5851E-05" iyz="3.6027E-07" izz="5.6992E-05"/>
    </inertial>
    <visual>
      <origin rpy="0 0 0" xyz="0 0 0"/>
      <geometry>
        <mesh filename="file:///home/office/zbot_ws/install/zbot_description/share/zbot_description/meshes/LEP_link.STL"/>
      </geometry>
      <material name="">
        <color rgba="1 1 1 1"/>
      </material>
    </visual>
    <collision name="LEP_link_main">
      <origin rpy="0 0 0" xyz="0 0.025 -0.093"/>
      <geometry>
        <cylinder length="0.05" radius="0.03"/>
      </geometry>
    </collision>
    <collision name="LEP_link_mount">
      <origin rpy="0 0 0" xyz="0 0 -0.03"/>
      <geometry>
        <box size="0.05 0.005 0.08"/>
      </geometry>
    </collision>
  </link>
  <joint name="LEP_joint" type="revolute">
    <origin rpy="0 0 0" xyz="-1.4714E-05 -0.028015 -0.22617"/>
    <parent link="LSR_link"/>
    <child link="LEP_link"/>
    <axis xyz="0 -1 0"/>
    <limit effort="25" lower="-1.57" upper="1.57" velocity="10.47"/>
    <dynamics damping="0.05" friction="0.05"/>
  </joint>
  <link name="LWR_link">
    <inertial>
      <origin rpy="0 0 0" xyz="2.1426E-10 0.0050603 -0.04305"/>
      <mass value="0.15675"/>
      <inertia ixx="5.9396E-05" ixy="-6.1312E-13" ixz="-5.7068E-09" iyy="5.8786E-05" iyz="6.5271E-07" izz="5.9559E-05"/>
    </inertial>
    <visual>
      <origin rpy="0 0 0" xyz="0 0 0"/>
      <geometry>
        <mesh filename="file:///home/office/zbot_ws/install/zbot_description/share/zbot_description/meshes/LWR_link.STL"/>
      </geometry>
      <material name="">
        <color rgba="1 1 1 1"/>
      </material>
    </visual>
    <collision name="LWR_link_main">
      <origin rpy="1.57 0 0" xyz="0 0 -0.053"/>
      <geometry>
        <cylinder length="0.05" radius="0.03"/>
      </geometry>
    </collision>
    <collision name="LWR_link_mount">
      <origin rpy="0 0 0" xyz="0 0.03 -0.033"/>
      <geometry>
        <box size="0.05 0.004 0.06"/>
      </geometry>
    </collision>
  </link>
  <joint name="LWR_joint" type="revolute">
    <origin rpy="0 0 0" xyz="0 0.0235 -0.1244"/>
    <parent link="LEP_link"/>
    <child link="LWR_link"/>
    <axis xyz="0 0 1"/>
    <limit effort="7" lower="-1.57" upper="1.57" velocity="10.47"/>
    <dynamics damping="0.05" friction="0.05"/>
  </joint>
  <link name="LWP_link">
    <inertial>
      <origin rpy="0 0 0" xyz="-0.0016414 0.025392 -0.064653"/>
      <mass value="0.17262"/>
      <inertia ixx="6.9076E-05" ixy="6.1312E-13" ixz="-2.1656E-06" iyy="7.0471E-05" iyz="3.4482E-06" izz="6.5933E-05"/>
    </inertial>
    <visual>
      <origin rpy="0 0 0" xyz="0 0 0"/>
      <geometry>
        <mesh filename="file:///home/office/zbot_ws/install/zbot_description/share/zbot_description/meshes/LWP_link.STL"/>
      </geometry>
      <material name="">
        <color rgba="1 1 1 1"/>
      </material>
    </visual>
    <collision name="LWP_link_main">
      <origin rpy="0 1.57 0" xyz="-0.0015 0.026 -0.078"/>
      <geometry>
        <cylinder length="0.053" radius="0.03"/>
      </geometry>
    </collision>
    <collision name="LWP_link_mount">
      <origin rpy="0 0 0" xyz="0 0 -0.0115"/>
      <geometry>
        <box size="0.036 0.004 0.056"/>
      </geometry>
    </collision>
    <collision name="LWP_link_mount1">
      <origin rpy="0 0 0" xyz="-0.027 0.028 -0.0442"/>
      <geometry>
        <box size="0.003 0.0271 0.0124"/>
      </geometry>
    </collision>
    <collision name="LWP_link_mount2">
      <origin rpy="0 0 0" xyz="-0.0027 0.0212 -0.038"/>
      <geometry>
        <box size="0.0415 0.0435 0.006"/>
      </geometry>
    </collision>
  </link>
  <joint name="LWP_joint" type="revolute">
    <origin rpy="0 0 0" xyz="0 -0.0284 -0.049899"/>
    <parent link="LWR_link"/>
    <child link="LWP_link"/>
    <axis xyz="0 1 0"/>
    <limit effort="7" lower="-1.57" upper="1.57" velocity="10.47"/>
    <dynamics damping="0.05" friction="0.05"/>
  </joint>
  <link name="LWY_link">
    <inertial>
      <origin rpy="0 0 0" xyz="-0.025989 -8.234E-07 -0.072885"/>
      <mass value="0.14311"/>
      <inertia ixx="0.0001351" ixy="-2.218E-09" ixz="-3.6162E-06" iyy="3.6435E-05" iyz="3.4239E-10" izz="0.00014744"/>
    </inertial>
    <visual>
      <origin rpy="0 0 0" xyz="0 0 0"/>
      <geometry>
        <mesh filename="file:///home/office/zbot_ws/install/zbot_description/share/zbot_description/meshes/LWY_link.STL"/>
      </geometry>
      <material name="">
        <color rgba="0.86667 0.9098 1 1"/>
      </material>
    </visual>
    <collision name="lWY_link_main">
      <origin rpy="0 0 0" xyz="-0.0304 0 -0.0583"/>
      <geometry>
        <cylinder length="0.0471" radius="0.023"/>
      </geometry>
    </collision>
    <collision name="lWY_link_mount">
      <origin rpy="0 0 0" xyz="0 0 -0.0075"/>
      <geometry>
        <box size="0.003 0.04 0.055"/>
      </geometry>
    </collision>
    <collision name="lWY_link_pinion">
      <origin rpy="0 0 0" xyz="-0.0304 0 -0.094"/>
      <geometry>
        <box size="0.0535 0.126 0.024"/>
      </geometry>
    </collision>
  </link>
  <joint name="LWY_joint" type="revolute">
    <origin rpy="0 0 0" xyz="0.0304 0.0284 -0.076"/>
    <parent link="LWP_link"/>
    <child link="LWY_link"/>
    <axis xyz="-1 0 0"/>
    <limit effort="7" lower="-1.57" upper="1.57" velocity="10.47"/>
    <dynamics damping="0.05" friction="0.05"/>
  </joint>
  <link name="LGRF_link">
    <inertial>
      <origin rpy="0 0 0" xyz="-1.2815E-08 1.2259E-05 -0.0098954"/>
      <mass value="0.025769"/>
      <inertia ixx="4.2118E-06" ixy="-6.2859E-22" ixz="-1.6764E-21" iyy="1.2066E-05" iyz="1.8787E-07" izz="8.6788E-06"/>
    </inertial>
    <visual>
      <origin rpy="0 0 0" xyz="0 0 0"/>
      <geometry>
        <mesh filename="file:///home/office/zbot_ws/install/zbot_description/share/zbot_description/meshes/LGRF_link.STL"/>
      </geometry>
      <material name="">
        <color rgba="1 1 1 1"/>
      </material>
    </visual>
    <collision name="LGRF_link_box">
      <origin rpy="0 0 0" xyz="0 0 -0.016"/>
      <geometry>
        <box size="0.0535 0.014 0.035"/>
      </geometry>
    </collision>
  </link>
  <joint name="LGRF_joint" type="prismatic">
    <origin rpy="0 0 0" xyz="-0.0304 -0.0515 -0.10975"/>
    <parent link="LWY_link"/>
    <child link="LGRF_link"/>
    <axis xyz="0 1 0"/>
    <limit effort="1.8" lower="0" upper="0.04" velocity="0.3"/>
    <dynamics damping="0.05" friction="0.05"/>
  </joint>
  <link name="LGLF_link">
    <inertial>
      <origin rpy="0 0 0" xyz="-8.5901E-13 -1.2259E-05 -0.0098955"/>
      <mass value="0.025769"/>
      <inertia ixx="4.2118E-06" ixy="4.3305E-21" ixz="-1.2399E-21" iyy="1.2066E-05" iyz="-1.8787E-07" izz="8.6788E-06"/>
    </inertial>
    <visual>
      <origin rpy="0 0 0" xyz="0 0 0"/>
      <geometry>
        <mesh filename="file:///home/office/zbot_ws/install/zbot_description/share/zbot_description/meshes/LGLF_link.STL"/>
      </geometry>
      <material name="">
        <color rgba="1 1 1 1"/>
      </material>
    </visual>
    <collision name="LGLF_link_box">
      <origin rpy="0 0 0" xyz="0 0 -0.016"/>
      <geometry>
        <box size="0.0535 0.014 0.035"/>
      </geometry>
    </collision>
  </link>
  <joint name="LGLF_joint" type="prismatic">
    <origin rpy="0 0 0" xyz="-0.0304 0.0515 -0.10975"/>
    <parent link="LWY_link"/>
    <child link="LGLF_link"/>
    <axis xyz="0 1 0"/>
    <mimic joint="LGRF_joint" multiplier="-1.0"/>
    <limit effort="1.8" lower="-0.04" upper="0" velocity="0.3"/>
    <dynamics damping="0.05" friction="0.05"/>
  </joint>
  <joint name="base_to_torso" type="fixed">
    <parent link="top_box_link"/>
    <child link="torso_footprint"/>
    <origin rpy="0 0 0" xyz="0 0 0.01"/>
  </joint>
</robot>
