<?xml version="1.0" ?>
<robot name="zbot">
  <link name="base_link">
    <inertial>
      <origin rpy="0 0 0" xyz="0.000969769171030282 -2.51743070833754E-14 0.112038367342421"/>
      <mass value="16.3990394222604"/>
      <inertia ixx="0.380637346168345" ixy="-0.148651077561082" ixz="-0.000152996884277864" iyy="0.389495977304953" iyz="3.71624735443284E-16" izz="0.616293577235193"/>
    </inertial>
    <visual>
      <origin rpy="0 0 0" xyz="0 0 0"/>
      <geometry>
        <mesh filename="file:///home/office/zbot_ws/install/zbot_description/share/zbot_description/meshes/base_link.STL"/>
      </geometry>
      <material name="">
        <color rgba="0.792156862745098 0.819607843137255 0.933333333333333 1"/>
      </material>
    </visual>
    <collision>
      <origin rpy="0 0 0" xyz="0 0 0"/>
      <geometry>
        <mesh filename="file:///home/office/zbot_ws/install/zbot_description/share/zbot_description/meshes/base_link.STL"/>
      </geometry>
    </collision>
  </link>
  <link name="base_footprint"/>
  <joint name="basefootprint_to_base" type="fixed">
    <parent link="base_footprint"/>
    <child link="base_link"/>
    <origin rpy="0 0 0" xyz="0 0 0.06"/>
  </joint>
  <link name="top_box_link">
    <visual>
      <origin rpy="0 0 0" xyz="0 0 0"/>
      <geometry>
        <box size="0.45 0.45 0.02"/>
      </geometry>
      <material name="">
        <color rgba="0.6 0.6 0.6 1"/>
      </material>
    </visual>
    <collision>
      <origin rpy="0 0 0" xyz="0 0 0"/>
      <geometry>
        <box size="0.45 0.45 0.02"/>
      </geometry>
    </collision>
    <inertial>
      <origin rpy="0 0 0" xyz="0 0 0"/>
      <mass value="1.0"/>
      <inertia ixx="0.01" ixy="0.0" ixz="0.0" iyy="0.01" iyz="0.0" izz="0.01"/>
    </inertial>
  </link>
  <joint name="base_to_top_box" type="fixed">
    <parent link="base_link"/>
    <child link="top_box_link"/>
    <origin rpy="0 0 0" xyz="0 0 0.26"/>
  </joint>
  <link name="Rigthwheel_Link">
    <inertial>
      <origin rpy="0 0 0" xyz="-2.77555756156289E-17 -0.0172531056477295 3.46944695195361E-17"/>
      <mass value="0.422964399925245"/>
      <inertia ixx="0.000450352731222891" ixy="2.93305874890802E-19" ixz="7.95950128490977E-22" iyy="0.000799166716964206" iyz="-6.96192737487882E-19" izz="0.000450352731222891"/>
    </inertial>
    <visual>
      <origin rpy="0 0 0" xyz="0 0 0"/>
      <geometry>
        <mesh filename="file:///home/office/zbot_ws/install/zbot_description/share/zbot_description/meshes/Rigthwheel_Link.STL"/>
      </geometry>
      <material name="">
        <color rgba="0.792156862745098 0.819607843137255 0.933333333333333 1"/>
      </material>
    </visual>
    <collision>
      <origin rpy="0 0 0" xyz="0 0 0"/>
      <geometry>
        <mesh filename="file:///home/office/zbot_ws/install/zbot_description/share/zbot_description/meshes/Rigthwheel_Link.STL"/>
      </geometry>
    </collision>
  </link>
  <joint name="Rigthwheel_joint" type="continuous">
    <origin rpy="0 0 3.14" xyz="0 0.195500000000004 0"/>
    <parent link="base_link"/>
    <child link="Rigthwheel_Link"/>
    <axis xyz="0 -1 0"/>
  </joint>
  <link name="Leftwheel_Link">
    <inertial>
      <origin rpy="0 0 0" xyz="-2.77555756156289E-17 0.0172531056477295 6.93889390390723E-18"/>
      <mass value="0.422964399925245"/>
      <inertia ixx="0.000450352731222891" ixy="-1.63319545033364E-21" ixz="-1.17067365193491E-20" iyy="0.000799166716964206" iyz="1.71286555130685E-20" izz="0.000450352731222891"/>
    </inertial>
    <visual>
      <origin rpy="0 0 0" xyz="0 0 0"/>
      <geometry>
        <mesh filename="file:///home/office/zbot_ws/install/zbot_description/share/zbot_description/meshes/Leftwheel_Link.STL"/>
      </geometry>
      <material name="">
        <color rgba="0.792156862745098 0.819607843137255 0.933333333333333 1"/>
      </material>
    </visual>
    <collision>
      <origin rpy="0 0 0" xyz="0 0 0"/>
      <geometry>
        <mesh filename="file:///home/office/zbot_ws/install/zbot_description/share/zbot_description/meshes/Leftwheel_Link.STL"/>
      </geometry>
    </collision>
  </link>
  <joint name="Leftwheel_joint" type="continuous">
    <origin rpy="0 0 0" xyz="0 -0.1955 0"/>
    <parent link="base_link"/>
    <child link="Leftwheel_Link"/>
    <axis xyz="0 1 0"/>
    <limit effort="24" velocity="0.58875"/>
  </joint>
  <link name="Holder1_Link">
    <inertial>
      <origin rpy="0 0 0" xyz="0.0149538369402379 -2.77555756156289E-17 -0.00548508947688804"/>
      <mass value="0.0807915502778827"/>
      <inertia ixx="2.45834344225308E-05" ixy="1.69021364418985E-20" ixz="3.88786622376317E-06" iyy="2.66654394263947E-05" iyz="-3.31005941315939E-21" izz="4.19580790977868E-05"/>
    </inertial>
    <visual>
      <origin rpy="0 0 0" xyz="0 0 0"/>
      <geometry>
        <mesh filename="file:///home/office/zbot_ws/install/zbot_description/share/zbot_description/meshes/Holder1_Link.STL"/>
      </geometry>
      <material name="">
        <color rgba="0.647058823529412 0.619607843137255 0.588235294117647 1"/>
      </material>
    </visual>
    <collision>
      <origin rpy="0 0 0" xyz="0 0 0"/>
      <geometry>
        <mesh filename="file:///home/office/zbot_ws/install/zbot_description/share/zbot_description/meshes/Holder1_Link.STL"/>
      </geometry>
    </collision>
  </link>
  <joint name="Holder1_joint" type="continuous">
    <origin rpy="0 0 0" xyz="0.13 0.1295 -0.0075"/>
    <parent link="base_link"/>
    <child link="Holder1_Link"/>
    <axis xyz="0 0 -1"/>
    <limit effort="0" velocity="0"/>
  </joint>
  <link name="Wheel1_Link">
    <inertial>
      <origin rpy="0 0 0" xyz="4.64905891561784E-16 -1.38777878078145E-17 8.23126289350995E-16"/>
      <mass value="0.07386669726753"/>
      <inertia ixx="1.38792446386636E-05" ixy="-6.31654242534127E-22" ixz="-1.59131939955441E-22" iyy="2.33141763250642E-05" iyz="2.23754762315135E-22" izz="1.38792446386636E-05"/>
    </inertial>
    <visual>
      <origin rpy="0 0 0" xyz="0 0 0"/>
      <geometry>
        <mesh filename="file:///home/office/zbot_ws/install/zbot_description/share/zbot_description/meshes/Wheel1_Link.STL"/>
      </geometry>
      <material name="">
        <color rgba="0.298039215686275 0.298039215686275 0.298039215686275 1"/>
      </material>
    </visual>
    <collision>
      <origin rpy="0 0 0" xyz="0 0 0"/>
      <geometry>
        <mesh filename="file:///home/office/zbot_ws/install/zbot_description/share/zbot_description/meshes/Wheel1_Link.STL"/>
      </geometry>
    </collision>
  </link>
  <joint name="Wheel1_joint" type="continuous">
    <origin rpy="0 0 0" xyz="0.035 0 -0.03"/>
    <parent link="Holder1_Link"/>
    <child link="Wheel1_Link"/>
    <axis xyz="0 1 0"/>
    <limit effort="0" velocity="0"/>
  </joint>
  <link name="Holder2_Link">
    <inertial>
      <origin rpy="0 0 0" xyz="0.0149538369402379 -1.38777878078145E-17 -0.00548508947688804"/>
      <mass value="0.0807915502778826"/>
      <inertia ixx="2.45834344225309E-05" ixy="1.74611051724873E-20" ixz="3.88786622376317E-06" iyy="2.66654394263947E-05" iyz="-2.67449956498734E-21" izz="4.19580790977868E-05"/>
    </inertial>
    <visual>
      <origin rpy="0 0 0" xyz="0 0 0"/>
      <geometry>
        <mesh filename="file:///home/office/zbot_ws/install/zbot_description/share/zbot_description/meshes/Holder2_Link.STL"/>
      </geometry>
      <material name="">
        <color rgba="0.647058823529412 0.619607843137255 0.588235294117647 1"/>
      </material>
    </visual>
    <collision>
      <origin rpy="0 0 0" xyz="0 0 0"/>
      <geometry>
        <mesh filename="file:///home/office/zbot_ws/install/zbot_description/share/zbot_description/meshes/Holder2_Link.STL"/>
      </geometry>
    </collision>
  </link>
  <joint name="Holder2_joint" type="continuous">
    <origin rpy="0 0 0" xyz="-0.13 0.1295 -0.0075"/>
    <parent link="base_link"/>
    <child link="Holder2_Link"/>
    <axis xyz="0 0 -1"/>
    <limit effort="0" velocity="0"/>
  </joint>
  <link name="Wheel2_Link">
    <inertial>
      <origin rpy="0 0 0" xyz="0 -1.38777878078145E-17 3.46944695195361E-18"/>
      <mass value="0.07386669726753"/>
      <inertia ixx="1.38792446386636E-05" ixy="-7.66357158702502E-22" ixz="-1.57821214113715E-22" iyy="2.33141763250642E-05" iyz="2.33184621298239E-22" izz="1.38792446386636E-05"/>
    </inertial>
    <visual>
      <origin rpy="0 0 0" xyz="0 0 0"/>
      <geometry>
        <mesh filename="file:///home/office/zbot_ws/install/zbot_description/share/zbot_description/meshes/Wheel2_Link.STL"/>
      </geometry>
      <material name="">
        <color rgba="0.298039215686275 0.298039215686275 0.298039215686275 1"/>
      </material>
    </visual>
    <collision>
      <origin rpy="0 0 0" xyz="0 0 0"/>
      <geometry>
        <mesh filename="file:///home/office/zbot_ws/install/zbot_description/share/zbot_description/meshes/Wheel2_Link.STL"/>
      </geometry>
    </collision>
  </link>
  <joint name="Wheel2_joint" type="continuous">
    <origin rpy="0 0 0" xyz="0.035 0 -0.03"/>
    <parent link="Holder2_Link"/>
    <child link="Wheel2_Link"/>
    <axis xyz="0 1 0"/>
    <limit effort="0" velocity="0"/>
  </joint>
  <link name="Holder3_Link">
    <inertial>
      <origin rpy="0 0 0" xyz="0.0149538369402379 5.55111512312578E-17 -0.00548508947688803"/>
      <mass value="0.0807915502778826"/>
      <inertia ixx="2.45834344225309E-05" ixy="-6.06702902396125E-20" ixz="3.88786622376317E-06" iyy="2.66654394263947E-05" iyz="7.11922492648378E-20" izz="4.19580790977868E-05"/>
    </inertial>
    <visual>
      <origin rpy="0 0 0" xyz="0 0 0"/>
      <geometry>
        <mesh filename="file:///home/office/zbot_ws/install/zbot_description/share/zbot_description/meshes/Holder3_Link.STL"/>
      </geometry>
      <material name="">
        <color rgba="0.647058823529412 0.619607843137255 0.588235294117647 1"/>
      </material>
    </visual>
    <collision>
      <origin rpy="0 0 0" xyz="0 0 0"/>
      <geometry>
        <mesh filename="file:///home/office/zbot_ws/install/zbot_description/share/zbot_description/meshes/Holder3_Link.STL"/>
      </geometry>
    </collision>
  </link>
  <joint name="Holder3_joint" type="continuous">
    <origin rpy="0 0 0" xyz="0.13 -0.1295 -0.0075"/>
    <parent link="base_link"/>
    <child link="Holder3_Link"/>
    <axis xyz="0 0 -1"/>
    <limit effort="0" velocity="0"/>
  </joint>
  <link name="Wheel3_Link">
    <inertial>
      <origin rpy="0 0 0" xyz="5.55111512312578E-17 0 3.25260651745651E-18"/>
      <mass value="0.0738666972675301"/>
      <inertia ixx="1.38792446386636E-05" ixy="-7.75197651499163E-22" ixz="-1.17777958037584E-22" iyy="2.33141763250642E-05" iyz="2.24802524424369E-22" izz="1.38792446386636E-05"/>
    </inertial>
    <visual>
      <origin rpy="0 0 0" xyz="0 0 0"/>
      <geometry>
        <mesh filename="file:///home/office/zbot_ws/install/zbot_description/share/zbot_description/meshes/Wheel3_Link.STL"/>
      </geometry>
      <material name="">
        <color rgba="0.298039215686275 0.298039215686275 0.298039215686275 1"/>
      </material>
    </visual>
    <collision>
      <origin rpy="0 0 0" xyz="0 0 0"/>
      <geometry>
        <mesh filename="file:///home/office/zbot_ws/install/zbot_description/share/zbot_description/meshes/Wheel3_Link.STL"/>
      </geometry>
    </collision>
  </link>
  <joint name="Wheel3_joint" type="continuous">
    <origin rpy="0 0 0" xyz="0.035 0 -0.03"/>
    <parent link="Holder3_Link"/>
    <child link="Wheel3_Link"/>
    <axis xyz="0 1 0"/>
    <limit effort="0" velocity="0"/>
  </joint>
  <link name="Holder4_Link">
    <inertial>
      <origin rpy="0 0 0" xyz="0.0149538369402378 5.55111512312578E-17 -0.00548508947688803"/>
      <mass value="0.0807915502778826"/>
      <inertia ixx="2.45834344225309E-05" ixy="-6.43861401513826E-20" ixz="3.88786622376317E-06" iyy="2.66654394263947E-05" iyz="6.03905506479546E-20" izz="4.19580790977869E-05"/>
    </inertial>
    <visual>
      <origin rpy="0 0 0" xyz="0 0 0"/>
      <geometry>
        <mesh filename="file:///home/office/zbot_ws/install/zbot_description/share/zbot_description/meshes/Holder4_Link.STL"/>
      </geometry>
      <material name="">
        <color rgba="0.647058823529412 0.619607843137255 0.588235294117647 1"/>
      </material>
    </visual>
    <collision>
      <origin rpy="0 0 0" xyz="0 0 0"/>
      <geometry>
        <mesh filename="file:///home/office/zbot_ws/install/zbot_description/share/zbot_description/meshes/Holder4_Link.STL"/>
      </geometry>
    </collision>
  </link>
  <joint name="Holder4_joint" type="continuous">
    <origin rpy="0 0 0" xyz="-0.13 -0.1295 -0.0075"/>
    <parent link="base_link"/>
    <child link="Holder4_Link"/>
    <axis xyz="0 0 -1"/>
    <limit effort="0" velocity="0"/>
  </joint>
  <link name="Wheel4_Link">
    <inertial>
      <origin rpy="0 0 0" xyz="1.66533453693773E-16 0 5.76795555762288E-17"/>
      <mass value="0.0738666972675301"/>
      <inertia ixx="1.38792446386636E-05" ixy="-7.74739255576373E-22" ixz="-1.16467232195857E-22" iyy="2.33141763250642E-05" iyz="2.3318462129824E-22" izz="1.38792446386636E-05"/>
    </inertial>
    <visual>
      <origin rpy="0 0 0" xyz="0 0 0"/>
      <geometry>
        <mesh filename="file:///home/office/zbot_ws/install/zbot_description/share/zbot_description/meshes/Wheel4_Link.STL"/>
      </geometry>
      <material name="">
        <color rgba="0.298039215686275 0.298039215686275 0.298039215686275 1"/>
      </material>
    </visual>
    <collision>
      <origin rpy="0 0 0" xyz="0 0 0"/>
      <geometry>
        <mesh filename="file:///home/office/zbot_ws/install/zbot_description/share/zbot_description/meshes/Wheel4_Link.STL"/>
      </geometry>
    </collision>
  </link>
  <joint name="Wheel4_joint" type="continuous">
    <origin rpy="0 0 0" xyz="0.035 0 -0.03"/>
    <parent link="Holder4_Link"/>
    <child link="Wheel4_Link"/>
    <axis xyz="0 1 0"/>
    <limit effort="0" velocity="0"/>
  </joint>

  <link name="torso_footprint"/>
  <link name="torso_link">
    <inertial>
      <origin rpy="0 0 0" xyz="0.018596 -3.9839E-08 -0.30971"/>
      <mass value="8.7003"/>
      <inertia ixx="1.648" ixy="0.00000078" ixz="0.084" iyy="1.655" iyz="0.000" izz="0.045"/>
    </inertial>
    <visual>
      <origin rpy="0 0 0" xyz="0 0 0"/>
      <geometry>
        <mesh filename="file:///home/office/zbot_ws/install/zbot_description/share/zbot_description/meshes/torso_link.STL"/>
      </geometry>
      <material name="">
        <color rgba="1 1 1 1"/>
      </material>
    </visual>
    <collision>
      <origin rpy="0 0 0" xyz="0 0 0"/>
      <geometry>
        <mesh filename="file:///home/office/zbot_ws/install/zbot_description/share/zbot_description/meshes/torso_link.STL"/>
      </geometry>
    </collision>
  </link>
  <joint name="footprint_to_torso" type="fixed">
    <parent link="torso_footprint"/>
    <child link="torso_link"/>
    <origin rpy="0 0 0" xyz="0 0 1.085"/>
  </joint>
  <link name="T2RS_link">
    <inertial>
      <origin rpy="0 0 0" xyz="-0.00003285 -0.042916 0.0483"/>
      <mass value="1.25"/>
      <inertia ixx="0.0014" ixy="-0.00000046" ixz="-0.00000037" iyy="0.0016" iyz="-0.000491" izz="0.0012"/>
    </inertial>
    <visual>
      <origin rpy="0 0 0" xyz="0 0 0"/>
      <geometry>
        <mesh filename="file:///home/office/zbot_ws/install/zbot_description/share/zbot_description/meshes/T2RS_link.STL"/>
      </geometry>
      <material name="">
        <color rgba="0.89412 0.89412 0.89412 1"/>
      </material>
    </visual>
    <collision>
      <origin rpy="1.44 0 0" xyz="0 -0.046 0.06"/>
      <geometry>
        <cylinder length="0.06" radius="0.053"/>
      </geometry>
    </collision>
  </link>
  <joint name="T2RS_joint" type="fixed">
    <origin rpy="0 0 0" xyz="0 -0.062 -0.046174"/>
    <parent link="torso_link"/>
    <child link="T2RS_link"/>
    <axis xyz="0 0 0"/>
  </joint>
  <link name="RSP_link">
    <inertial>
      <origin rpy="0 0 0" xyz="-0.0016 -0.066 -0.0000528"/>
      <mass value="0.935"/>
      <inertia ixx="0.00034" ixy="0.0000066" ixz="0.00000014" iyy="0.0001685" iyz="0.00000023" izz="0.0002959"/>
    </inertial>
    <visual>
      <origin rpy="0 0 0" xyz="0 0 0"/>
      <geometry>
        <mesh filename="file:///home/office/zbot_ws/install/zbot_description/share/zbot_description/meshes/RSP_link.STL"/>
      </geometry>
      <material name="">
        <color rgba="0.86667 0.9098 1 1"/>
      </material>
    </visual>
    <!-- Main cylindrical body -->
    <collision>
      <origin rpy="0 1.57 0" xyz="0 -0.068 0"/>
      <geometry>
        <cylinder length="0.05" radius="0.053"/>
      </geometry>
    </collision>
    <!-- Side mounting bracket -->
    <collision>
      <origin rpy="0 0 0" xyz="0 -0.0125 0"/>
      <geometry>
        <box size="0.05 0.02 0.05"/>
      </geometry>
    </collision>
  </link>
  <joint name="RSP_joint" type="revolute">
    <origin rpy="-0.13963 0 0" xyz="0 -0.078272 0.065888"/>
    <parent link="T2RS_link"/>
    <child link="RSP_link"/>
    <axis xyz="0 1 0"/>
    <limit effort="35" lower="-1.57" upper="1.57" velocity="10.47"/>
    <dynamics damping="0.05" friction="0.05"/>
  </joint>
  <link name="RSY_link">
    <inertial>
      <origin rpy="0 0 0" xyz="-0.00694 -8.3267E-17 -0.037821"/>
      <mass value="0.053339"/>
      <inertia ixx="0.0000598" ixy="8.1403E-22" ixz="-8.1208E-07" iyy="0.00006" iyz="-7.2518E-21" izz="0.000015"/>
    </inertial>
    <visual>
      <origin rpy="0 0 0" xyz="0 0 0"/>
      <geometry>
        <mesh filename="file:///home/office/zbot_ws/install/zbot_description/share/zbot_description/meshes/RSY_link.STL"/>
      </geometry>
      <material name="">
        <color rgba="0.86667 0.9098 1 1"/>
      </material>
    </visual>
    <collision>
      <!-- Vertical plate -->
      <origin rpy="0 0 0" xyz="0 0 -0.03"/>
      <geometry>
        <box size="0.01 0.05 0.09"/>
      </geometry>
    </collision>
    <collision>
      <!-- Bottom horizontal plate -->
      <origin rpy="0 0 0" xyz="-0.02 0 -0.065"/>
      <geometry>
        <box size="0.05 0.05 0.01"/>
      </geometry>
    </collision>
  </link>
  <joint name="RSY_joint" type="revolute">
    <origin rpy="0.13963 0 0" xyz="0.031 -0.06875 0"/>
    <parent link="RSP_link"/>
    <child link="RSY_link"/>
    <axis xyz="-1 0 0"/>
    <limit effort="35" lower="-1.57" upper="1.57" velocity="10.47"/>
    <dynamics damping="0.05" friction="0.05"/>
  </joint>
  <link name="RSR_link">
    <inertial>
      <origin rpy="0 0 0" xyz="0.000114 0.0000884 -0.1211"/>
      <mass value="1.458"/>
      <inertia ixx="0.01462" ixy="-0.00000027" ixz="-0.00001678" iyy="0.01464" iyz="-0.00004242" izz="0.00051252"/>
    </inertial>
    <visual>
      <origin rpy="0 0 0" xyz="0 0 0"/>
      <geometry>
        <mesh filename="file:///home/office/zbot_ws/install/zbot_description/share/zbot_description/meshes/RSR_link.STL"/>
      </geometry>
      <material name="">
        <color rgba="0.89412 0.89412 0.89412 1"/>
      </material>
    </visual>
    <collision name="RSR_link_middlepart">
      <origin rpy="0 0 0" xyz="0 0 -0.09"/>
      <geometry>
        <cylinder length="0.18" radius="0.055"/>
      </geometry>
    </collision>
    <collision name="RSR_link_elbowmotor">
      <origin rpy="1.57 0 0" xyz="0 0 -0.23"/>
      <geometry>
        <cylinder length="0.06" radius="0.05"/>
      </geometry>
    </collision>
  </link>
  <joint name="RSR_joint" type="revolute">
    <origin rpy="0 0 0" xyz="-0.0275 0 -0.07875"/>
    <parent link="RSY_link"/>
    <child link="RSR_link"/>
    <axis xyz="0 0 1"/>
    <limit effort="25" lower="-1.57" upper="1.57" velocity="10.47"/>
    <dynamics damping="0.05" friction="0.05"/>
  </joint>
  <link name="REP_link">
    <inertial>
      <origin rpy="0 0 0" xyz="0.00 -0.0215 -0.088"/>
      <mass value="0.343"/>
      <inertia ixx="2.8488E-04" ixy="-5.7068E-09" ixz="8.1084E-10" iyy="2.7E-04" iyz="-3.6027E-07" izz="1.3992E-04"/>
    </inertial>
    <visual>
      <origin rpy="0 0 0" xyz="0 0 0"/>
      <geometry>
        <mesh filename="file:///home/office/zbot_ws/install/zbot_description/share/zbot_description/meshes/REP_link.STL"/>
      </geometry>
      <material name="">
        <color rgba="1 1 1 1"/>
      </material>
    </visual>
    <collision name="REP_link_main">
      <origin rpy="0 0 0" xyz="0 -0.025 -0.093"/>
      <geometry>
        <cylinder length="0.05" radius="0.03"/>
      </geometry>
    </collision>
    <collision name="REP_link_mount">
      <origin rpy="0 0 0" xyz="0 0 -0.03"/>
      <geometry>
        <box size="0.05 0.005 0.08"/>
      </geometry>
    </collision>
  </link>
  <joint name="REP_joint" type="revolute">
    <origin rpy="0 0 0" xyz="1.4698E-05 0.028015 -0.22617"/>
    <parent link="RSR_link"/>
    <child link="REP_link"/>
    <axis xyz="0 1 0"/>
    <limit effort="25" lower="-1.57" upper="1.57" velocity="10.47"/>
    <dynamics damping="0.05" friction="0.05"/>
  </joint>
  <link name="RWR_link">
    <inertial>
      <origin rpy="0 0 0" xyz="0 0.003 -0.046"/>
      <mass value="0.34"/>
      <inertia ixx="0.0002" ixy="0.00" ixz="0.00" iyy="1.7E-04" iyz="1.091E-05" izz="0.000144"/>
    </inertial>
    <visual>
      <origin rpy="0 0 0" xyz="0 0 0"/>
      <geometry>
        <mesh filename="file:///home/office/zbot_ws/install/zbot_description/share/zbot_description/meshes/RWR_link.STL"/>
      </geometry>
      <material name="">
        <color rgba="1 1 1 1"/>
      </material>
    </visual>
    <collision name="RWR_link_main">
      <origin rpy="1.57 0 0" xyz="0 0 -0.053"/>
      <geometry>
        <cylinder length="0.05" radius="0.03"/>
      </geometry>
    </collision>
    <collision name="RWR_link_mount">
      <origin rpy="0 0 0" xyz="0 0.03 -0.033"/>
      <geometry>
        <box size="0.05 0.004 0.06"/>
      </geometry>
    </collision>
  </link>
  <joint name="RWR_joint" type="revolute">
    <origin rpy="0 0 0" xyz="0 -0.0235 -0.1244"/>
    <parent link="REP_link"/>
    <child link="RWR_link"/>
    <axis xyz="0 0 1"/>
    <limit effort="7" lower="-1.57" upper="1.57" velocity="10.47"/>
    <dynamics damping="0.05" friction="0.05"/>
  </joint>
  <link name="RWP_link">
    <inertial>
      <origin rpy="0 0 0" xyz="-0.0009 0.027 -0.0705"/>
      <mass value="0.3547"/>
      <inertia ixx="2.3076E-04" ixy="-0.00000047" ixz="-0.00" iyy="2.3076E-04" iyz="-2.9482E-05" izz="0.000154"/>
    </inertial>
    <visual>
      <origin rpy="0 0 0" xyz="0 0 0"/>
      <geometry>
        <mesh filename="file:///home/office/zbot_ws/install/zbot_description/share/zbot_description/meshes/RWP_link.STL"/>
      </geometry>
      <material name="">
        <color rgba="1 1 1 1"/>
      </material>
    </visual>
    <collision name="RWP_link_main">
      <origin rpy="0 1.57 0" xyz="-0.0015 0.026 -0.078"/>
      <geometry>
        <cylinder length="0.053" radius="0.03"/>
      </geometry>
    </collision>
    <collision name="RWP_link_mount">
      <origin rpy="0 0 0" xyz="0 0 -0.0115"/>
      <geometry>
        <box size="0.036 0.004 0.056"/>
      </geometry>
    </collision>
    <collision name="RWP_link_mount1">
      <origin rpy="0 0 0" xyz="-0.027 0.028 -0.0442"/>
      <geometry>
        <box size="0.003 0.0271 0.0124"/>
      </geometry>
    </collision>
    <collision name="RWP_link_mount2">
      <origin rpy="0 0 0" xyz="-0.0027 0.0212 -0.038"/>
      <geometry>
        <box size="0.0415 0.0435 0.006"/>
      </geometry>
    </collision>
  </link>
  <joint name="RWP_joint" type="revolute">
    <origin rpy="0 0 0" xyz="0 -0.0284 -0.049899"/>
    <parent link="RWR_link"/>
    <child link="RWP_link"/>
    <axis xyz="0 1 0"/>
    <limit effort="7" lower="-1.57" upper="1.57" velocity="10.47"/>
    <dynamics damping="0.05" friction="0.05"/>
  </joint>
  <link name="RWY_link">
    <inertial>
      <origin rpy="0 0 0" xyz="-0.0285 -0.00000275 -0.0670885"/>
      <mass value="0.356"/>
      <inertia ixx="0.00037" ixy="-2.35E-06" ixz="3.461E-05" iyy="2.945E-04" iyz="-3.4239E-8" izz="0.0002523"/>
    </inertial>
    <visual>
      <origin rpy="0 0 0" xyz="0 0 0"/>
      <geometry>
        <mesh filename="file:///home/office/zbot_ws/install/zbot_description/share/zbot_description/meshes/RWY_link.STL"/>
      </geometry>
      <material name="">
        <color rgba="1 1 1 1"/>
      </material>
    </visual>
    <collision name="RWY_link_main">
      <origin rpy="0 0 0" xyz="-0.0304 0 -0.0583"/>
      <geometry>
        <cylinder length="0.0471" radius="0.023"/>
      </geometry>
    </collision>
    <collision name="RWY_link_mount">
      <origin rpy="0 0 0" xyz="0 0 -0.0075"/>
      <geometry>
        <box size="0.003 0.04 0.055"/>
      </geometry>
    </collision>
    <collision name="RWY_link_pinion">
      <origin rpy="0 0 0" xyz="-0.0304 0 -0.094"/>
      <geometry>
        <box size="0.0535 0.126 0.024"/>
      </geometry>
    </collision>
  </link>
  <joint name="RWY_joint" type="revolute">
    <origin rpy="0 0 0" xyz="0.0304 0.0284 -0.076"/>
    <parent link="RWP_link"/>
    <child link="RWY_link"/>
    <axis xyz="-1 0 0"/>
    <limit effort="7" lower="-1.57" upper="1.57" velocity="10.47"/>
    <dynamics damping="0.05" friction="0.05"/>
  </joint>
  <link name="RGRF_link">
    <inertial>
      <origin rpy="0 0 0" xyz="-1.4993E-10 1.2259E-05 -0.0098954"/>
      <mass value="0.025769"/>
      <inertia ixx="4.2118E-06" ixy="1.4492E-22" ixz="6.0762E-22" iyy="1.2066E-05" iyz="1.8787E-07" izz="8.6788E-06"/>
    </inertial>
    <visual>
      <origin rpy="0 0 0" xyz="0 0 0"/>
      <geometry>
        <mesh filename="file:///home/office/zbot_ws/install/zbot_description/share/zbot_description/meshes/RGRF_link.STL"/>
      </geometry>
      <material name="">
        <color rgba="1 1 1 1"/>
      </material>
    </visual>
    <collision name="RGRF_link_box">
      <origin rpy="0 0 0" xyz="0 0 -0.016"/>
      <geometry>
        <box size="0.0535 0.014 0.035"/>
      </geometry>
    </collision>
  </link>
  <joint name="RGRF_joint" type="prismatic">
    <origin rpy="0 0 0" xyz="-0.0304 -0.0515 -0.10975"/>
    <parent link="RWY_link"/>
    <child link="RGRF_link"/>
    <axis xyz="0 1 0"/>
    <limit effort="1.8" lower="0" upper="0.04" velocity="0.3"/>
  </joint>
  <link name="RGLF_link">
    <inertial>
      <origin rpy="0 0 0" xyz="1.0343E-11 -1.2259E-05 -0.0098955"/>
      <mass value="0.025769"/>
      <inertia ixx="4.2118E-06" ixy="-3.6494E-22" ixz="2.7143E-21" iyy="1.2066E-05" iyz="-1.8787E-07" izz="8.6788E-06"/>
    </inertial>
    <visual>
      <origin rpy="0 0 0" xyz="0 0 0"/>
      <geometry>
        <mesh filename="file:///home/office/zbot_ws/install/zbot_description/share/zbot_description/meshes/RGLF_link.STL"/>
      </geometry>
      <material name="">
        <color rgba="1 1 1 1"/>
      </material>
    </visual>
    <collision name="RGLF_link_box">
      <origin rpy="0 0 0" xyz="0 0 -0.016"/>
      <geometry>
        <box size="0.0535 0.014 0.035"/>
      </geometry>
    </collision>
  </link>
  <joint name="RGLF_joint" type="prismatic">
    <origin rpy="0 0 0" xyz="-0.0304 0.0515 -0.10975"/>
    <parent link="RWY_link"/>
    <child link="RGLF_link"/>
    <axis xyz="0 1 0"/>
    <mimic joint="RGRF_joint" multiplier="-1.0"/>
    <limit effort="1.8" lower="-0.04" upper="0" velocity="0.3"/>
    <dynamics damping="0.05" friction="0.05"/>
  </joint>
  <link name="T2LS_link">
    <inertial>
      <origin rpy="0 0 0" xyz="0.000033 0.0434 0.0483"/>
      <mass value="1.2523"/>
      <inertia ixx="0.00144" ixy="-1.1182E-07" ixz="6.3739E-08" iyy="0.00163" iyz="0.0005" izz="0.0012"/>
    </inertial>
    <visual>
      <origin rpy="0 0 0" xyz="0 0 0"/>
      <geometry>
        <mesh filename="file:///home/office/zbot_ws/install/zbot_description/share/zbot_description/meshes/T2LS_link.STL"/>
      </geometry>
      <material name="">
        <color rgba="0.77647 0.75686 0.73725 1"/>
      </material>
    </visual>
    <collision>
      <origin rpy="1.7 0 0" xyz="0 0.046 0.06"/>
      <geometry>
        <cylinder length="0.06" radius="0.053"/>
      </geometry>
    </collision>
  </link>
  <joint name="T2LS_joint" type="fixed">
    <origin rpy="0 0 0" xyz="0 0.061536 -0.046174"/>
    <parent link="torso_link"/>
    <child link="T2LS_link"/>
    <axis xyz="0 0 0"/>
  </joint>
  <link name="LSP_link">
    <inertial>
      <origin rpy="0 0 0" xyz="-0.0016 0.0658 0.00005"/>
      <mass value="0.9356"/>
      <inertia ixx="0.00034" ixy="-6.5408E-06" ixz="1.0612E-06" iyy="0.00017" iyz="0.000018" izz="0.00029"/>
    </inertial>
    <visual>
      <origin rpy="0 0 0" xyz="0 0 0"/>
      <geometry>
        <mesh filename="file:///home/office/zbot_ws/install/zbot_description/share/zbot_description/meshes/LSP_link.STL"/>
      </geometry>
      <material name="">
        <color rgba="0.86667 0.9098 1 1"/>
      </material>
    </visual>
    <collision>
      <origin rpy="0 1.57 0" xyz="0 0.068 0"/>
      <geometry>
        <cylinder length="0.05" radius="0.053"/>
      </geometry>
    </collision>
    <!-- Side mounting bracket -->
    <collision>
      <origin rpy="0 0 0" xyz="0 0.0125 0"/>
      <geometry>
        <box size="0.05 0.02 0.05"/>
      </geometry>
    </collision>
  </link>
  <joint name="LSP_joint" type="revolute">
    <origin rpy="0.13963 0 0" xyz="0 0.078736 0.065888"/>
    <parent link="T2LS_link"/>
    <child link="LSP_link"/>
    <axis xyz="0 -1 0"/>
    <limit effort="35" lower="-1.57" upper="1.57" velocity="10.47"/>
    <dynamics damping="0.05" friction="0.05"/>
  </joint>
  <link name="LSY_link">
    <inertial>
      <origin rpy="0 0 0" xyz="-0.00694 -4.0801E-15 -0.037821"/>
      <mass value="0.053339"/>
      <inertia ixx="0.00006" ixy="-1.2859E-21" ixz="-8.1208E-07" iyy="0.00006035" iyz="-1.4228E-20" izz="0.000015"/>
    </inertial>
    <visual>
      <origin rpy="0 0 0" xyz="0 0 0"/>
      <geometry>
        <mesh filename="file:///home/office/zbot_ws/install/zbot_description/share/zbot_description/meshes/LSY_link.STL"/>
      </geometry>
      <material name="">
        <color rgba="1 1 1 1"/>
      </material>
    </visual>
    <collision>
      <!-- Vertical plate -->
      <origin rpy="0 0 0" xyz="0 0 -0.03"/>
      <geometry>
        <box size="0.01 0.05 0.09"/>
      </geometry>
    </collision>
    <collision>
      <!-- Bottom horizontal plate -->
      <origin rpy="0 0 0" xyz="-0.02 0 -0.065"/>
      <geometry>
        <box size="0.05 0.05 0.01"/>
      </geometry>
    </collision>
  </link>
  <joint name="LSY_joint" type="revolute">
    <origin rpy="-0.13963 0 0" xyz="0.031 0.06875 0"/>
    <parent link="LSP_link"/>
    <child link="LSY_link"/>
    <axis xyz="-1 0 0"/>
    <limit effort="35" lower="-1.57" upper="1.57" velocity="10.47"/>
    <dynamics damping="0.05" friction="0.05"/>
  </joint>
  <link name="LSR_link">
    <inertial>
      <origin rpy="0 0 0" xyz="-0.000111 -0.0003 -0.121"/>
      <mass value="1.458"/>
      <inertia ixx="0.0146" ixy="0.00" ixz="0.0000172" iyy="0.014641" iyz="0.000012" izz="0.000512"/>
    </inertial>
    <visual>
      <origin rpy="0 0 0" xyz="0 0 0"/>
      <geometry>
        <mesh filename="file:///home/office/zbot_ws/install/zbot_description/share/zbot_description/meshes/LSR_link.STL"/>
      </geometry>
      <material name="">
        <color rgba="0.89412 0.89412 0.89412 1"/>
      </material>
    </visual>
    <collision name="LSR_link_middlepart">
      <origin rpy="0 0 0" xyz="0 0 -0.09"/>
      <geometry>
        <cylinder length="0.18" radius="0.055"/>
      </geometry>
    </collision>
    <collision name="LSR_link_elbowmotor">
      <origin rpy="1.57 0 0" xyz="0 0 -0.23"/>
      <geometry>
        <cylinder length="0.06" radius="0.05"/>
      </geometry>
    </collision>
  </link>
  <joint name="LSR_joint" type="revolute">
    <origin rpy="0 0 0" xyz="-0.0275 0 -0.07875"/>
    <parent link="LSY_link"/>
    <child link="LSR_link"/>
    <axis xyz="0 0 1"/>
    <limit effort="25" lower="-1.57" upper="1.57" velocity="10.47"/>
    <dynamics damping="0.05" friction="0.05"/>
  </joint>
  <link name="LEP_link">
    <inertial>
      <origin rpy="0 0 0" xyz="0.00 0.0215 -0.088"/>
      <mass value="0.3427"/>
      <inertia ixx="0.00028" ixy="0.00" ixz="0.00" iyy="0.000271" iyz="-0.00004" izz="0.000144"/>
    </inertial>
    <visual>
      <origin rpy="0 0 0" xyz="0 0 0"/>
      <geometry>
        <mesh filename="file:///home/office/zbot_ws/install/zbot_description/share/zbot_description/meshes/LEP_link.STL"/>
      </geometry>
      <material name="">
        <color rgba="1 1 1 1"/>
      </material>
    </visual>
    <collision name="LEP_link_main">
      <origin rpy="0 0 0" xyz="0 0.025 -0.093"/>
      <geometry>
        <cylinder length="0.05" radius="0.03"/>
      </geometry>
    </collision>
    <collision name="LEP_link_mount">
      <origin rpy="0 0 0" xyz="0 0 -0.03"/>
      <geometry>
        <box size="0.05 0.005 0.08"/>
      </geometry>
    </collision>
  </link>
  <joint name="LEP_joint" type="revolute">
    <origin rpy="0 0 0" xyz="-1.4714E-05 -0.028015 -0.22617"/>
    <parent link="LSR_link"/>
    <child link="LEP_link"/>
    <axis xyz="0 -1 0"/>
    <limit effort="25" lower="-1.57" upper="1.57" velocity="10.47"/>
    <dynamics damping="0.05" friction="0.05"/>
  </joint>
  <link name="LWR_link">
    <inertial>
      <origin rpy="0 0 0" xyz="0.00 0.0035 -0.0467"/>
      <mass value="0.339"/>
      <inertia ixx="0.0018" ixy="0.00" ixz="0.00" iyy="0.00017" iyz="0.000011" izz="0.000144"/>
    </inertial>
    <visual>
      <origin rpy="0 0 0" xyz="0 0 0"/>
      <geometry>
        <mesh filename="file:///home/office/zbot_ws/install/zbot_description/share/zbot_description/meshes/LWR_link.STL"/>
      </geometry>
      <material name="">
        <color rgba="1 1 1 1"/>
      </material>
    </visual>
    <collision name="LWR_link_main">
      <origin rpy="1.57 0 0" xyz="0 0 -0.053"/>
      <geometry>
        <cylinder length="0.05" radius="0.03"/>
      </geometry>
    </collision>
    <collision name="LWR_link_mount">
      <origin rpy="0 0 0" xyz="0 0.03 -0.033"/>
      <geometry>
        <box size="0.05 0.004 0.06"/>
      </geometry>
    </collision>
  </link>
  <joint name="LWR_joint" type="revolute">
    <origin rpy="0 0 0" xyz="0 0.0235 -0.1244"/>
    <parent link="LEP_link"/>
    <child link="LWR_link"/>
    <axis xyz="0 0 1"/>
    <limit effort="7" lower="-1.57" upper="1.57" velocity="10.47"/>
    <dynamics damping="0.05" friction="0.05"/>
  </joint>
  <link name="LWP_link">
    <inertial>
      <origin rpy="0 0 0" xyz="-0.0009 0.027 -0.07048"/>
      <mass value="0.3547"/>
      <inertia ixx="0.000237" ixy="0.00" ixz="-0.0000026" iyy="0.000235" iyz="-0.00003" izz="0.000154"/>
    </inertial>
    <visual>
      <origin rpy="0 0 0" xyz="0 0 0"/>
      <geometry>
        <mesh filename="file:///home/office/zbot_ws/install/zbot_description/share/zbot_description/meshes/LWP_link.STL"/>
      </geometry>
      <material name="">
        <color rgba="1 1 1 1"/>
      </material>
    </visual>
    <collision name="LWP_link_main">
      <origin rpy="0 1.57 0" xyz="-0.0015 0.026 -0.078"/>
      <geometry>
        <cylinder length="0.053" radius="0.03"/>
      </geometry>
    </collision>
    <collision name="LWP_link_mount">
      <origin rpy="0 0 0" xyz="0 0 -0.0115"/>
      <geometry>
        <box size="0.036 0.004 0.056"/>
      </geometry>
    </collision>
    <collision name="LWP_link_mount1">
      <origin rpy="0 0 0" xyz="-0.027 0.028 -0.0442"/>
      <geometry>
        <box size="0.003 0.0271 0.0124"/>
      </geometry>
    </collision>
    <collision name="LWP_link_mount2">
      <origin rpy="0 0 0" xyz="-0.0027 0.0212 -0.038"/>
      <geometry>
        <box size="0.0415 0.0435 0.006"/>
      </geometry>
    </collision>
  </link>
  <joint name="LWP_joint" type="revolute">
    <origin rpy="0 0 0" xyz="0 -0.0284 -0.049899"/>
    <parent link="LWR_link"/>
    <child link="LWP_link"/>
    <axis xyz="0 1 0"/>
    <limit effort="7" lower="-1.57" upper="1.57" velocity="10.47"/>
    <dynamics damping="0.05" friction="0.05"/>
  </joint>
  <link name="LWY_link">
    <inertial>
      <origin rpy="0 0 0" xyz="-0.0285 -2.75E-06 -0.0672"/>
      <mass value="0.356"/>
      <inertia ixx="0.000367" ixy="0.00" ixz="3.462E-05" iyy="2.9435E-04" iyz="0.00" izz="0.00025"/>
    </inertial>
    <visual>
      <origin rpy="0 0 0" xyz="0 0 0"/>
      <geometry>
        <mesh filename="file:///home/office/zbot_ws/install/zbot_description/share/zbot_description/meshes/LWY_link.STL"/>
      </geometry>
      <material name="">
        <color rgba="0.86667 0.9098 1 1"/>
      </material>
    </visual>
    <collision name="lWY_link_main">
      <origin rpy="0 0 0" xyz="-0.0304 0 -0.0583"/>
      <geometry>
        <cylinder length="0.0471" radius="0.023"/>
      </geometry>
    </collision>
    <collision name="lWY_link_mount">
      <origin rpy="0 0 0" xyz="0 0 -0.0075"/>
      <geometry>
        <box size="0.003 0.04 0.055"/>
      </geometry>
    </collision>
    <collision name="lWY_link_pinion">
      <origin rpy="0 0 0" xyz="-0.0304 0 -0.094"/>
      <geometry>
        <box size="0.0535 0.126 0.024"/>
      </geometry>
    </collision>
  </link>
  <joint name="LWY_joint" type="revolute">
    <origin rpy="0 0 0" xyz="0.0304 0.0284 -0.076"/>
    <parent link="LWP_link"/>
    <child link="LWY_link"/>
    <axis xyz="-1 0 0"/>
    <limit effort="7" lower="-1.57" upper="1.57" velocity="10.47"/>
    <dynamics damping="0.05" friction="0.05"/>
  </joint>
  <link name="LGRF_link">
    <inertial>
      <origin rpy="0 0 0" xyz="-1.2815E-08 1.2259E-05 -0.0098954"/>
      <mass value="0.025769"/>
      <inertia ixx="4.2118E-06" ixy="-6.2859E-22" ixz="-1.6764E-21" iyy="1.2066E-05" iyz="1.8787E-07" izz="8.6788E-06"/>
    </inertial>
    <visual>
      <origin rpy="0 0 0" xyz="0 0 0"/>
      <geometry>
        <mesh filename="file:///home/office/zbot_ws/install/zbot_description/share/zbot_description/meshes/LGRF_link.STL"/>
      </geometry>
      <material name="">
        <color rgba="1 1 1 1"/>
      </material>
    </visual>
    <collision name="LGRF_link_box">
      <origin rpy="0 0 0" xyz="0 0 -0.016"/>
      <geometry>
        <box size="0.0535 0.014 0.035"/>
      </geometry>
    </collision>
  </link>
  <joint name="LGRF_joint" type="prismatic">
    <origin rpy="0 0 0" xyz="-0.0304 -0.0515 -0.10975"/>
    <parent link="LWY_link"/>
    <child link="LGRF_link"/>
    <axis xyz="0 1 0"/>
    <limit effort="1.8" lower="0" upper="0.04" velocity="0.3"/>
    <dynamics damping="0.05" friction="0.05"/>
  </joint>
  <link name="LGLF_link">
    <inertial>
      <origin rpy="0 0 0" xyz="-8.5901E-13 -1.2259E-05 -0.0098955"/>
      <mass value="0.025769"/>
      <inertia ixx="4.2118E-06" ixy="4.3305E-21" ixz="-1.2399E-21" iyy="1.2066E-05" iyz="-1.8787E-07" izz="8.6788E-06"/>
    </inertial>
    <visual>
      <origin rpy="0 0 0" xyz="0 0 0"/>
      <geometry>
        <mesh filename="file:///home/office/zbot_ws/install/zbot_description/share/zbot_description/meshes/LGLF_link.STL"/>
      </geometry>
      <material name="">
        <color rgba="1 1 1 1"/>
      </material>
    </visual>
    <collision name="LGLF_link_box">
      <origin rpy="0 0 0" xyz="0 0 -0.016"/>
      <geometry>
        <box size="0.0535 0.014 0.035"/>
      </geometry>
    </collision>
  </link>
  <joint name="LGLF_joint" type="prismatic">
    <origin rpy="0 0 0" xyz="-0.0304 0.0515 -0.10975"/>
    <parent link="LWY_link"/>
    <child link="LGLF_link"/>
    <axis xyz="0 1 0"/>
    <mimic joint="LGRF_joint" multiplier="-1.0"/>
    <limit effort="1.8" lower="-0.04" upper="0" velocity="0.3"/>
    <dynamics damping="0.05" friction="0.05"/>
  </joint>
  <joint name="base_to_torso" type="fixed">
    <parent link="top_box_link"/>
    <child link="torso_footprint"/>
    <origin rpy="0 0 0" xyz="0 0 0.01"/>
  </joint>
</robot>
