<?xml version="1.0" encoding="utf-8"?>
<robot
  name="zbot">
  <link
    name="chassis_link">
    <inertial>
      <origin
        xyz="4.1242009807263E-13 -1.41053835278626E-13 0.0457150612516181"
        rpy="0 0 0" />
      <mass
        value="2.91418586484034" />
      <inertia
        ixx="0.0160414554493788"
        ixy="-3.80532779283033E-08"
        ixz="5.2791865716338E-15"
        iyy="0.0223949877952289"
        iyz="3.03477371110732E-16"
        izz="0.0344217543051772" />
    </inertial>
    <visual>
      <origin
        xyz="0 0 0"
        rpy="0 0 0" />
      <geometry>
        <mesh
          filename="file://$(env HOME)/zbot_ws/install/zbot_description/share/zbot_description/meshes/chassis_link.STL" />
      </geometry>
      <material
        name="">
        <color
          rgba="0.792156862745098 0.819607843137255 0.933333333333333 1" />
      </material>
    </visual>
    <collision>
      <origin
        xyz="0 0 0.12"
        rpy="0 0 0" />    
      <geometry>
        <box size="0.45 0.45 0.3"/>
      </geometry>
    </collision>
  </link>
  
  <link name="base_footprint"/>

  <joint name="basefootprint_to_chassis" type="fixed">
    <parent link="base_footprint"/>
    <child link="chassis_link"/>
    <origin xyz="0 0 0.06" rpy="0 0 0"/>
  </joint>  
 
  <link name="top_box_link">
    <visual>
      <origin xyz="0 0 0" rpy="0 0 0"/>
      <geometry>
        <box size="0.45 0.45 0.02"/>
      </geometry>
      <material name="">
        <color rgba="0.6 0.6 0.6 1"/>
      </material>
    </visual>

    <collision>
      <origin xyz="0 0 0" rpy="0 0 0"/>
      <geometry>
        <box size="0.45 0.45 0.02"/>
      </geometry>
    </collision>

    <inertial>
      <origin xyz="0 0 0" rpy="0 0 0"/>
      <mass value="1.0"/>
      <inertia
        ixx="0.01" ixy="0.0" ixz="0.0"
        iyy="0.01" iyz="0.0"
        izz="0.01"/>
    </inertial>
  </link>

  <joint name="chassis_to_top_box" type="fixed">
    <parent link="chassis_link"/>
    <child link="top_box_link"/>
    <origin xyz="0 0 0.26" rpy="0 0 0"/>
  </joint> 
  
  <link
    name="Left_wheel_link">
    <inertial>
      <origin
        xyz="1.38777878078145E-16 0.0172531056477295 7.63278329429795E-16"
        rpy="0 0 0" />
      <mass
        value="0.422964399925245" />
      <inertia
        ixx="0.000450352731222891"
        ixy="8.63588855368215E-21"
        ixz="-2.55358655482607E-20"
        iyy="0.000799166716964205"
        iyz="-1.56617535979576E-20"
        izz="0.000450352731222891" />
    </inertial>
    <visual>
      <origin
        xyz="0 0 0"
        rpy="0 0 0" />
      <geometry>
        <mesh
          filename="file://$(env HOME)/zbot_ws/install/zbot_description/share/zbot_description/meshes/Left_wheel_link.STL" />
      </geometry>
      <material
        name="">
        <color
          rgba="0.792156862745098 0.819607843137255 0.933333333333333 1" />
      </material>
    </visual>
    <collision>
      <origin
        xyz="0 0 0"
        rpy="0 0 0" />
      <geometry>
        <mesh
          filename="file://$(env HOME)/zbot_ws/install/zbot_description/share/zbot_description/meshes/Left_wheel_link.STL" />
      </geometry>
    </collision>
  </link>
  <joint
    name="Left_wheel_joint"
    type="continuous">
    <origin
      xyz="0 -0.195500000000004 0"
      rpy="0 0 0" />
    <parent
      link="chassis_link" />
    <child
      link="Left_wheel_link" />
    <axis
      xyz="0 1 0" />
    <limit
      effort="24"
      velocity="9.42" />
  </joint>
  <link
    name="Right_wheel_link">
    <inertial>
      <origin
        xyz="-1.66533453693773E-16 -0.0172531056477289 -4.16333634234434E-17"
        rpy="0 0 0" />
      <mass
        value="0.422964399925245" />
      <inertia
        ixx="0.000450352731222891"
        ixy="2.9978516071709E-19"
        ixz="1.86430677315541E-20"
        iyy="0.000799166716964206"
        iyz="-6.95386833210546E-19"
        izz="0.000450352731222891" />
    </inertial>
    <visual>
      <origin
        xyz="0 0 0"
        rpy="0 0 0" />
      <geometry>
        <mesh
          filename="file://$(env HOME)/zbot_ws/install/zbot_description/share/zbot_description/meshes/Right_wheel_link.STL" />
      </geometry>
      <material
        name="">
        <color
          rgba="0.792156862745098 0.819607843137255 0.933333333333333 1" />
      </material>
    </visual>
    <collision>
      <origin
        xyz="0 0 0"
        rpy="0 0 0" />
      <geometry>
        <mesh
          filename="file://$(env HOME)/zbot_ws/install/zbot_description/share/zbot_description/meshes/Right_wheel_link.STL" />
      </geometry>
    </collision>
  </link>
  <joint
    name="Right_wheel_joint"
    type="continuous">
    <origin
      xyz="0 0.195500000000003 0"
      rpy="0 0 0" />
    <parent
      link="chassis_link" />
    <child
      link="Right_wheel_link" />
    <axis
      xyz="0 -1 0" />
    <limit
      effort="24"
      velocity="9.42" />
  </joint>
  <link
    name="holder1_Link">
    <inertial>
      <origin
        xyz="0.0149538369402379 0 -0.00548508947688803"
        rpy="0 0 0" />
      <mass
        value="0.0110673356545045" />
      <inertia
        ixx="3.36759375651107E-06"
        ixy="1.91654214425208E-21"
        ixz="5.32584414214133E-07"
        iyy="3.65279992142393E-06"
        iyz="-2.64785319973256E-22"
        izz="5.74768206818997E-06" />
    </inertial>
    <visual>
      <origin
        xyz="0 0 0"
        rpy="0 0 0" />
      <geometry>
        <mesh
          filename="file://$(env HOME)/zbot_ws/install/zbot_description/share/zbot_description/meshes/holder1_Link.STL" />
      </geometry>
      <material
        name="">
        <color
          rgba="0 0 0 1" />
      </material>
    </visual>
    <collision>
      <origin
        xyz="0 0 0"
        rpy="0 0 0" />
      <geometry>
        <mesh
          filename="file://$(env HOME)/zbot_ws/install/zbot_description/share/zbot_description/meshes/holder1_Link.STL" />
      </geometry>
    </collision>
  </link>
  <joint
    name="holder1_joint"
    type="continuous">
    <origin
      xyz="0.13 0.1295 -0.00949999999999611"
      rpy="0 0 0" />
    <parent
      link="chassis_link" />
    <child
      link="holder1_Link" />
    <axis
      xyz="0 0 1" />
    <limit
      effort="0"
      velocity="0" />
  </joint>
  <link
    name="wheel1_Link">
    <inertial>
      <origin
        xyz="5.55111512312578E-17 0 3.25260651745651E-18"
        rpy="0 0 0" />
      <mass
        value="0.07386669726753" />
      <inertia
        ixx="1.38792446386636E-05"
        ixy="-7.67863316734526E-22"
        ixz="-1.59131939955441E-22"
        iyy="2.33141763250642E-05"
        iyz="2.27558867913594E-22"
        izz="1.38792446386636E-05" />
    </inertial>
    <visual>
      <origin
        xyz="0 0 0"
        rpy="0 0 0" />
      <geometry>
        <mesh
          filename="file://$(env HOME)/zbot_ws/install/zbot_description/share/zbot_description/meshes/wheel1_Link.STL" />
      </geometry>
      <material
        name="">
        <color
          rgba="0.909803921568627 0.443137254901961 0.0313725490196078 1" />
      </material>
    </visual>
    <collision>
      <origin
        xyz="0 0 0"
        rpy="0 0 0" />
      <geometry>
        <mesh
          filename="file://$(env HOME)/zbot_ws/install/zbot_description/share/zbot_description/meshes/wheel1_Link.STL" />
      </geometry>
    </collision>
  </link>
  <joint
    name="wheel1_joint"
    type="continuous">
    <origin
      xyz="0.0350000000000004 0 -0.03"
      rpy="0 0 0" />
    <parent
      link="holder1_Link" />
    <child
      link="wheel1_Link" />
    <axis
      xyz="0 -1 0" />
    <limit
      effort="0"
      velocity="0" />
  </joint>
  <link
    name="holder2_Link">
    <inertial>
      <origin
        xyz="0.0149538369402378 -1.38777878078145E-17 -0.00548508947688803"
        rpy="0 0 0" />
      <mass
        value="0.0110673356545045" />
      <inertia
        ixx="3.36759375651108E-06"
        ixy="2.21298389542766E-21"
        ixz="5.32584414214133E-07"
        iyy="3.65279992142394E-06"
        iyz="-2.93180920139946E-22"
        izz="5.74768206818998E-06" />
    </inertial>
    <visual>
      <origin
        xyz="0 0 0"
        rpy="0 0 0" />
      <geometry>
        <mesh
          filename="file://$(env HOME)/zbot_ws/install/zbot_description/share/zbot_description/meshes/holder2_Link.STL" />
      </geometry>
      <material
        name="">
        <color
          rgba="0 0 0 1" />
      </material>
    </visual>
    <collision>
      <origin
        xyz="0 0 0"
        rpy="0 0 0" />
      <geometry>
        <mesh
          filename="file://$(env HOME)/zbot_ws/install/zbot_description/share/zbot_description/meshes/holder2_Link.STL" />
      </geometry>
    </collision>
  </link>
  <joint
    name="holder2_joint"
    type="continuous">
    <origin
      xyz="-0.130000000000001 0.1295 -0.00949999999999698"
      rpy="0 0 0" />
    <parent
      link="chassis_link" />
    <child
      link="holder2_Link" />
    <axis
      xyz="0 0 1" />
    <limit
      effort="0"
      velocity="0" />
  </joint>
  <link
    name="wheel2_Link">
    <inertial>
      <origin
        xyz="5.55111512312578E-17 -1.38777878078145E-17 3.25260651745651E-18"
        rpy="0 0 0" />
      <mass
        value="0.07386669726753" />
      <inertia
        ixx="1.38792446386636E-05"
        ixy="-7.67404920811736E-22"
        ixz="-1.57821214113714E-22"
        iyy="2.33141763250642E-05"
        iyz="2.36988726896699E-22"
        izz="1.38792446386636E-05" />
    </inertial>
    <visual>
      <origin
        xyz="0 0 0"
        rpy="0 0 0" />
      <geometry>
        <mesh
          filename="file://$(env HOME)/zbot_ws/install/zbot_description/share/zbot_description/meshes/wheel2_Link.STL" />
      </geometry>
      <material
        name="">
        <color
          rgba="0.909803921568627 0.443137254901961 0.0313725490196078 1" />
      </material>
    </visual>
    <collision>
      <origin
        xyz="0 0 0"
        rpy="0 0 0" />
      <geometry>
        <mesh
          filename="file://$(env HOME)/zbot_ws/install/zbot_description/share/zbot_description/meshes/wheel2_Link.STL" />
      </geometry>
    </collision>
  </link>
  <joint
    name="wheel2_joint"
    type="continuous">
    <origin
      xyz="0.0350000000000004 0 -0.03"
      rpy="0 0 0" />
    <parent
      link="holder2_Link" />
    <child
      link="wheel2_Link" />
    <axis
      xyz="0 -1 0" />
    <limit
      effort="0"
      velocity="0" />
  </joint>
  <link
    name="holder3_Link">
    <inertial>
      <origin
        xyz="0.0149538369402379 1.11022302462516E-16 -0.00548508947688804"
        rpy="0 0 0" />
      <mass
        value="0.0110673356545045" />
      <inertia
        ixx="3.36759375651107E-06"
        ixy="-8.59900995484746E-21"
        ixz="5.32584414214132E-07"
        iyy="3.65279992142393E-06"
        iyz="9.43655140551764E-21"
        izz="5.74768206818997E-06" />
    </inertial>
    <visual>
      <origin
        xyz="0 0 0"
        rpy="0 0 0" />
      <geometry>
        <mesh
          filename="file://$(env HOME)/zbot_ws/install/zbot_description/share/zbot_description/meshes/holder3_Link.STL" />
      </geometry>
      <material
        name="">
        <color
          rgba="0 0 0 1" />
      </material>
    </visual>
    <collision>
      <origin
        xyz="0 0 0"
        rpy="0 0 0" />
      <geometry>
        <mesh
          filename="file://$(env HOME)/zbot_ws/install/zbot_description/share/zbot_description/meshes/holder3_Link.STL" />
      </geometry>
    </collision>
  </link>
  <joint
    name="holder3_joint"
    type="continuous">
    <origin
      xyz="0.13 -0.1295 -0.00949999999999693"
      rpy="0 0 0" />
    <parent
      link="chassis_link" />
    <child
      link="holder3_Link" />
    <axis
      xyz="0 0 1" />
    <limit
      effort="0"
      velocity="0" />
  </joint>
  <link
    name="wheel3_Link">
    <inertial>
      <origin
        xyz="-2.91433543964104E-16 0 -8.16295815664336E-16"
        rpy="0 0 0" />
      <mass
        value="0.0738666972675301" />
      <inertia
        ixx="1.38792446386636E-05"
        ixy="-7.76245413608397E-22"
        ixz="-1.17777958037584E-22"
        iyy="2.33141763250642E-05"
        iyz="2.28606630022829E-22"
        izz="1.38792446386636E-05" />
    </inertial>
    <visual>
      <origin
        xyz="0 0 0"
        rpy="0 0 0" />
      <geometry>
        <mesh
          filename="file://$(env HOME)/zbot_ws/install/zbot_description/share/zbot_description/meshes/wheel3_Link.STL" />
      </geometry>
      <material
        name="">
        <color
          rgba="0.909803921568627 0.443137254901961 0.0313725490196078 1" />
      </material>
    </visual>
    <collision>
      <origin
        xyz="0 0 0"
        rpy="0 0 0" />
      <geometry>
        <mesh
          filename="file://$(env HOME)/zbot_ws/install/zbot_description/share/zbot_description/meshes/wheel3_Link.STL" />
      </geometry>
    </collision>
  </link>
  <joint
    name="wheel3_joint"
    type="continuous">
    <origin
      xyz="0.0350000000000007 0 -0.0299999999999991"
      rpy="0 0 0" />
    <parent
      link="holder3_Link" />
    <child
      link="wheel3_Link" />
    <axis
      xyz="0 -1 0" />
    <limit
      effort="0"
      velocity="0" />
  </joint>
  <link
    name="holder4_Link">
    <inertial>
      <origin
        xyz="0.0149538369402379 5.55111512312578E-17 -0.00548508947688803"
        rpy="0 0 0" />
      <mass
        value="0.0110673356545044" />
      <inertia
        ixx="3.36759375651107E-06"
        ixy="-5.99260130111312E-21"
        ixz="5.32584414214132E-07"
        iyy="3.65279992142393E-06"
        iyz="7.6641911408224E-21"
        izz="5.74768206818997E-06" />
    </inertial>
    <visual>
      <origin
        xyz="0 0 0"
        rpy="0 0 0" />
      <geometry>
        <mesh
          filename="file://$(env HOME)/zbot_ws/install/zbot_description/share/zbot_description/meshes/holder4_Link.STL" />
      </geometry>
      <material
        name="">
        <color
          rgba="0 0 0 1" />
      </material>
    </visual>
    <collision>
      <origin
        xyz="0 0 0"
        rpy="0 0 0" />
      <geometry>
        <mesh
          filename="file://$(env HOME)/zbot_ws/install/zbot_description/share/zbot_description/meshes/holder4_Link.STL" />
      </geometry>
    </collision>
  </link>
  <joint
    name="holder4_joint"
    type="continuous">
    <origin
      xyz="-0.13 -0.1295 -0.0095"
      rpy="0 0 0" />
    <parent
      link="chassis_link" />
    <child
      link="holder4_Link" />
    <axis
      xyz="0 0 1" />
    <limit
      effort="0"
      velocity="0" />
  </joint>
  <link
    name="wheel4_Link">
    <inertial>
      <origin
        xyz="3.33066907387547E-16 5.55111512312578E-17 1.63714528045311E-17"
        rpy="0 0 0" />
      <mass
        value="0.0738666972675301" />
      <inertia
        ixx="1.38792446386636E-05"
        ixy="-7.76834779794841E-22"
        ixz="-1.16467232195856E-22"
        iyy="2.33141763250642E-05"
        iyz="2.36988726896699E-22"
        izz="1.38792446386636E-05" />
    </inertial>
    <visual>
      <origin
        xyz="0 0 0"
        rpy="0 0 0" />
      <geometry>
        <mesh
          filename="file://$(env HOME)/zbot_ws/install/zbot_description/share/zbot_description/meshes/wheel4_Link.STL" />
      </geometry>
      <material
        name="">
        <color
          rgba="0.909803921568627 0.443137254901961 0.0313725490196078 1" />
      </material>
    </visual>
    <collision>
      <origin
        xyz="0 0 0"
        rpy="0 0 0" />
      <geometry>
        <mesh
          filename="file://$(env HOME)/zbot_ws/install/zbot_description/share/zbot_description/meshes/wheel4_Link.STL" />
      </geometry>
    </collision>
  </link>
  <joint
    name="wheel4_joint"
    type="continuous">
    <origin
      xyz="0.0350000000000001 0 -0.03"
      rpy="0 0 0" />
    <parent
      link="holder4_Link" />
    <child
      link="wheel4_Link" />
    <axis
      xyz="0 -1 0" />
    <limit
      effort="0"
      velocity="0" />
  </joint>
</robot>
